Workbook

Sheet Income Statement
A1: Palantir Technologies Inc. (PLTR) — Quarterly Financial Model
A2: ($ in thousands, except per-share data and percentages) · Fiscal year = calendar year
A3: Legend: A = Actual (reported) | E = Estimate (forecast, formula-driven off the Assumptions tab) | Blue font = hardcoded input | Black font = formula. See Sources tab for citations.
B4: FY2025 (Actual) | G4: FY2026 (Q1–Q2 Actual, Q3–Q4 Estimate) | L4: FY2027 (Estimate)
B5: Q1'25A | C5: Q2'25A | D5: Q3'25A | E5: Q4'25A | F5: FY2025A | G5: Q1'26A | H5: Q2'26A | I5: Q3'26E | J5: Q4'26E | K5: FY2026E | L5: Q1'27E | M5: Q2'27E | N5: Q3'27E | O5: Q4'27E | P5: FY2027E
A7: Revenue by Segment
A8: US Government | B8: 373000 | C8: 426100 | D8: 486000 | E8: 570000 | F8: =B8+C8+D8+E8 -> 1855100 | G8: 687000 | H8: 809000 | I8: =D8*(1+Assumptions!I8) -> 801900 | J8: =E8*(1+Assumptions!J8) -> 883500 | K8: =G8+H8+I8+J8 -> 3181400 | L8: =G8*(1+Assumptions!L8) -> 996150 | M8: =H8*(1+Assumptions!M8) -> 1132600 | N8: =I8*(1+Assumptions!N8) -> 1082565 | O8: =J8*(1+Assumptions!O8) -> 1148550 | P8: =L8+M8+N8+O8 -> 4359865
A9: US Commercial | B9: 255000 | C9: 306500 | D9: 397000 | E9: 507000 | F9: =B9+C9+D9+E9 -> 1465500 | G9: 595000 | H9: 764000 | I9: =D9*(1+Assumptions!I9) -> 794000 | J9: =E9*(1+Assumptions!J9) -> 937950 | K9: =G9+H9+I9+J9 -> 3090950 | L9: =G9*(1+Assumptions!L9) -> 1011500 | M9: =H9*(1+Assumptions!M9) -> 1222400 | N9: =I9*(1+Assumptions!N9) -> 1206880 | O9: =J9*(1+Assumptions!O9) -> 1360027.5 | P9: =L9+M9+N9+O9 -> 4800807.5
A10: International Government | B10: 113963 | C10: 126883 | D10: 146676 | E10: 159665 | F10: =B10+C10+D10+E10 -> 547187 | G10: 171410 | H10: 181032 | I10: =D10*(1+Assumptions!I10) -> 208279.92 | J10: =E10*(1+Assumptions!J10) -> 220337.7 | K10: =G10+H10+I10+J10 -> 781059.62 | L10: =G10*(1+Assumptions!L10) -> 229689.4 | M10: =H10*(1+Assumptions!M10) -> 235341.6 | N10: =I10*(1+Assumptions!N10) -> 264515.5 | O10: =J10*(1+Assumptions!O10) -> 273218.75 | P10: =L10+M10+N10+O10 -> 1002765.2
A11: International Commercial | B11: 141892 | C11: 144214 | D11: 151416 | E11: 170137 | F11: =B11+C11+D11+E11 -> 607659 | G11: 179173 | H11: 181432 | I11: =D11*(1+Assumptions!I11) -> 199869.12 | J11: =E11*(1+Assumptions!J11) -> 227983.58 | K11: =G11+H11+I11+J11 -> 788457.7 | L11: =G11*(1+Assumptions!L11) -> 241883.55 | M11: =H11*(1+Assumptions!M11) -> 244933.2 | N11: =I11*(1+Assumptions!N11) -> 265825.93 | O11: =J11*(1+Assumptions!O11) -> 296378.65 | P11: =L11+M11+N11+O11 -> 1049021.3
A13: Total US Revenue | B13: =B8+B9 -> 628000 | C13: =C8+C9 -> 732600 | D13: =D8+D9 -> 883000 | E13: =E8+E9 -> 1077000 | F13: =F8+F9 -> 3320600 | G13: =G8+G9 -> 1282000 | H13: =H8+H9 -> 1573000 | I13: =I8+I9 -> 1595900 | ... P13: =P8+P9 -> 9160672.5
A14: Total International Revenue | B14: =B10+B11 -> 255855 | C14: =C10+C11 -> 271097 | D14: =D10+D11 -> 298092 | E14: =E10+E11 -> 329802 | F14: =F10+F11 -> 1154846 | G14: =G10+G11 -> 350583 | H14: =H10+H11 -> 362464 | I14: =I10+I11 -> 408149.04 | ... P14: =P10+P11 -> 2051786.6
A15: Total Government Revenue | B15: =B8+B10 -> 486963 | C15: =C8+C10 -> 552983 | D15: =D8+D10 -> 632676 | E15: =E8+E10 -> 729665 | F15: =F8+F10 -> 2402287 | G15: =G8+G10 -> 858410 | H15: =H8+H10 -> 990032 | I15: =I8+I10 -> 1010179.9 | ... P15: =P8+P10 -> 5362630.2
A16: Total Commercial Revenue | B16: =B9+B11 -> 396892 | C16: =C9+C11 -> 450714 | D16: =D9+D11 -> 548416 | E16: =E9+E11 -> 677137 | F16: =F9+F11 -> 2073159 | G16: =G9+G11 -> 774173 | H16: =H9+H11 -> 945432 | I16: =I9+I11 -> 993869.12 | ... P16: =P9+P11 -> 5849828.8
A17: Total Revenue | B17: =B13+B14 -> 883855 | C17: =C13+C14 -> 1003697 | D17: =D13+D14 -> 1181092 | E17: =E13+E14 -> 1406802 | F17: =F13+F14 -> 4475446 | G17: =G13+G14 -> 1632583 | H17: =H13+H14 -> 1935464 | I17: =I13+I14 -> 2004049 | ... P17: =P13+P14 -> 11212459
A18: Check: Total Revenue (US+Intl) less (Gov+Comm) — should tie to 0 | B18: =B17-(B15+B16) -> 0 | C18: =C17-(C15+C16) -> 0 | D18: =D17-(D15+D16) -> 0 | E18: =E17-(E15+E16) -> 0 | F18: =F17-(F15+F16) -> 0 | G18: =G17-(G15+G16) -> 0 | H18: =H17-(H15+H16) -> 0 | I18: =I17-(I15+I16) -> 0 | ... P18: =P17-(P15+P16) -> 0
A20: US % of Total Revenue | B20: =B13/B17 -> 0.71052379 | C20: =C13/C17 -> 0.72990155 | D20: =D13/D17 -> 0.74761323 | E20: =E13/E17 -> 0.76556616 | F20: =F13/F17 -> 0.74195957 | G20: =G13/G17 -> 0.7852587 | H20: =H13/H17 -> 0.81272501 | I20: =I13/I17 -> 0.7963378 | ... P20: =P13/P17 -> 0.81700833
A21: International % of Total Revenue | B21: =B14/B17 -> 0.28947621 | C21: =C14/C17 -> 0.27009845 | D21: =D14/D17 -> 0.25238677 | E21: =E14/E17 -> 0.23443384 | F21: =F14/F17 -> 0.25804043 | G21: =G14/G17 -> 0.2147413 | H21: =H14/H17 -> 0.18727499 | I21: =I14/I17 -> 0.2036622 | ... P21: =P14/P17 -> 0.18299167
A22: Government % of Total Revenue | B22: =B15/B17 -> 0.55095349 | C22: =C15/C17 -> 0.55094615 | D22: =D15/D17 -> 0.53567038 | E22: =E15/E17 -> 0.51866929 | F22: =F15/F17 -> 0.53677041 | G22: =G15/G17 -> 0.52579869 | H22: =H15/H17 -> 0.51152178 | I22: =I15/I17 -> 0.50406946 | ... P22: =P15/P17 -> 0.47827423
A23: Commercial % of Total Revenue | B23: =B16/B17 -> 0.44904651 | C23: =C16/C17 -> 0.44905385 | D23: =D16/D17 -> 0.46432962 | E23: =E16/E17 -> 0.48133071 | F23: =F16/F17 -> 0.46322959 | G23: =G16/G17 -> 0.47420131 | H23: =H16/H17 -> 0.48847822 | I23: =I16/I17 -> 0.49593054 | ... P23: =P16/P17 -> 0.52172577
A25: Growth Rates
A26: Total Revenue — YoY % Growth | G26: =G17/B17-1 -> 0.84711633 | H26: =H17/C17-1 -> 0.92833495 | I26: =I17/D17-1 -> 0.69677641 | J26: =J17/E17-1 -> 0.61342625 | K26: =K17/F17-1 -> 0.75219795 | L26: =L17/G17-1 -> 0.51858922 | M26: =M17/H17-1 -> 0.46490702 | N26: =N17/I17-1 -> 0.40704462 | ... P26: =P17/K17-1 -> 0.42982004
A27: Total Revenue — QoQ % Growth | C27: =C17/B17-1 -> 0.13559011 | D27: =D17/C17-1 -> 0.17674159 | E27: =E17/D17-1 -> 0.19110281 | G27: =G17/E17-1 -> 0.16049238 | H27: =H17/G17-1 -> 0.18552257 | I27: =I17/H17-1 -> 0.035435968 | J27: =J17/I17-1 -> 0.13259268 | L27: =L17/J17-1 -> 0.092278756 | M27: =M17/L17-1 -> 0.14361429 | N27: =N17/M17-1 -> -0.005462741 | O27: =O17/N17-1 -> 0.091634058
A28: US Revenue — YoY % Growth | G28: =G13/B13-1 -> 1.0414013 | H28: =H13/C13-1 -> 1.1471471 | I28: =I13/D13-1 -> 0.80736127 | J28: =J13/E13-1 -> 0.69122563 | K28: =K13/F13-1 -> 0.88892068 | L28: =L13/G13-1 -> 0.56602964 | M28: =M13/H13-1 -> 0.49713922 | N28: =N13/I13-1 -> 0.43457923 | ... P28: =P13/K13-1 -> 0.46048491
A29: International Revenue — YoY % Growth | G29: =G14/B14-1 -> 0.37024096 | H29: =H14/C14-1 -> 0.33702697 | I29: =I14/D14-1 -> 0.36920494 | J29: =J14/E14-1 -> 0.35936495 | K29: =K14/F14-1 -> 0.35907066 | L29: =L14/G14-1 -> 0.34511072 | M29: =M14/H14-1 -> 0.32502759 | N29: =N14/I14-1 -> 0.29938178 | ... P29: =P14/K14-1 -> 0.30727234
A30: Government Revenue — YoY % Growth | G30: =G15/B15-1 -> 0.7627828 | H30: =H15/C15-1 -> 0.79034799 | I30: =I15/D15-1 -> 0.59667811 | J30: =J15/E15-1 -> 0.51280067 | K30: =K15/F15-1 -> 0.64945305 | L30: =L15/G15-1 -> 0.42803486 | M30: =M15/H15-1 -> 0.38171453 | N30: =N15/I15-1 -> 0.33350552 | ... P30: =P15/K15-1 -> 0.35335896
A31: Commercial Revenue — YoY % Growth | G31: =G16/B16-1 -> 0.95058857 | H31: =H16/C16-1 -> 1.0976318 | I31: =I16/D16-1 -> 0.81225406 | J31: =J16/E16-1 -> 0.72185773 | K31: =K16/F16-1 -> 0.8712543 | L31: =L16/G16-1 -> 0.61899672 | M31: =M16/H16-1 -> 0.55202405 | N31: =N16/I16-1 -> 0.48179061 | ... P31: =P16/K16-1 -> 0.50791803
A33: Income Statement
A34: Total Revenue | B34: =B17 -> 883855 | C34: =C17 -> 1003697 | D34: =D17 -> 1181092 | E34: =E17 -> 1406802 | F34: =F17 -> 4475446 | G34: =G17 -> 1632583 | H34: =H17 -> 1935464 | I34: =I17 -> 2004049 | ... P34: =P17 -> 11212459
A35: Cost of Revenue | B35: 172970 | C35: 192934 | D35: 207307 | E35: 215966 | F35: =B35+C35+D35+E35 -> 789177 | G35: 215798 | H35: 296870 | I35: =I34*(1-Assumptions!I14) -> 248502.08 | J35: =J34*(1-Assumptions!J14) -> 272372.55 | K35: =G35+H35+I35+J35 -> 1033542.6 | L35: =L34*(1-Assumptions!L14) -> 290069.09 | M35: =M34*(1-Assumptions!M14) -> 323221.33 | N35: =N34*(1-Assumptions!N14) -> 315816.08 | O35: =O34*(1-Assumptions!O14) -> 338599.24 | P35: =L35+M35+N35+O35 -> 1267705.7
A36: Gross Profit | B36: =B34-B35 -> 710885 | C36: =C34-C35 -> 810763 | D36: =D34-D35 -> 973785 | E36: =E34-E35 -> 1190836 | F36: =F34-F35 -> 3686269 | G36: =G34-G35 -> 1416785 | H36: =H34-H35 -> 1638594 | I36: =I34-I35 -> 1755547 | ... P36: =P34-P35 -> 9944753.3
A37: Gross Margin % | B37: =B36/B34 -> 0.80430048 | C37: =C36/C34 -> 0.80777665 | D37: =D36/D34 -> 0.82447853 | E37: =E36/E34 -> 0.84648444 | F37: =F36/F34 -> 0.82366517 | G37: =G36/G34 -> 0.86781805 | H37: =H36/H34 -> 0.84661559 | I37: =I36/I34 -> 0.876 | ... P37: =P36/P34 -> 0.88693776
A39: Sales & Marketing | B39: 236309 | C39: 243788 | D39: 274636 | E39: 302126 | F39: =B39+C39+D39+E39 -> 1056859 | G39: 319220 | H39: 339500 | I39: =I34*Assumptions!I15 -> 370749.07 | J39: =J34*Assumptions!J15 -> 408558.83 | K39: =G39+H39+I39+J39 -> 1438027.9 | L39: =L34*Assumptions!L15 -> 433864.02 | M39: =M34*Assumptions!M15 -> 481996.72 | N39: =N34*Assumptions!N15 -> 465264.76 | O39: =O34*Assumptions!O15 -> 492507.98 | P39: =L39+M39+N39+O39 -> 1873633.5
A40: % of Revenue | B40: =B39/B34 -> 0.26736173 | C40: =C39/C34 -> 0.24289004 | D40: =D39/D34 -> 0.23252719 | E40: =E39/E34 -> 0.21476085 | F40: =F39/F34 -> 0.23614607 | G40: =G39/G34 -> 0.19553064 | H40: =H39/H34 -> 0.17541013 | I40: =I39/I34 -> 0.185 | ... P40: =P39/P34 -> 0.16710282
A41: Research & Development | B41: 134889 | C41: 135043 | D41: 144191 | E41: 143554 | F41: =B41+C41+D41+E41 -> 557677 | G41: 160981 | H41: 192513 | I41: =I34*Assumptions!I16 -> 184372.51 | J41: =J34*Assumptions!J16 -> 204279.42 | K41: =G41+H41+I41+J41 -> 742145.93 | L41: =L34*Assumptions!L16 -> 218171.62 | M41: =M34*Assumptions!M16 -> 243833.63 | N41: =N34*Assumptions!N16 -> 236862.06 | O41: =O34*Assumptions!O16 -> 252410.34 | P41: =L41+M41+N41+O41 -> 951277.65
A42: % of Revenue | B42: =B41/B34 -> 0.1526144 | C42: =C41/C34 -> 0.13454558 | D42: =D41/D34 -> 0.12208278 | E42: =E41/E34 -> 0.10204279 | F42: =F41/F34 -> 0.12460814 | G42: =G41/G34 -> 0.098605094 | H42: =H41/H34 -> 0.099466071 | I42: =I41/I34 -> 0.092 | ... P42: =P41/P34 -> 0.084841126
A43: General & Administrative | B43: 163639 | C43: 162615 | D43: 161702 | E43: 169762 | F43: =B43+C43+D43+E43 -> 657718 | G43: 182586 | H43: 194577 | I43: =I34*Assumptions!I17 -> 210425.15 | J43: =J34*Assumptions!J17 -> 231516.67 | K43: =G43+H43+I43+J43 -> 819104.82 | L43: =L34*Assumptions!L17 -> 247922.3 | M43: =M34*Assumptions!M17 -> 277856.93 | N43: =N34*Assumptions!N17 -> 270699.5 | O43: =O34*Assumptions!O17 -> 289348.44 | P43: =L43+M43+N43+O43 -> 1085827.2
A44: % of Revenue | B44: =B43/B34 -> 0.18514236 | C44: =C43/C34 -> 0.16201603 | D44: =D43/D34 -> 0.13690889 | E44: =E43/E34 -> 0.12067228 | F44: =F43/F34 -> 0.14696144 | G44: =G43/G34 -> 0.11183872 | H44: =H43/H34 -> 0.10053248 | I44: =I43/I34 -> 0.105 | ... P44: =P43/P34 -> 0.096841126
A45: Total Operating Expenses | B45: =B39+B41+B43 -> 534837 | C45: =C39+C41+C43 -> 541446 | D45: =D39+D41+D43 -> 580529 | E45: =E39+E41+E43 -> 615442 | F45: =F39+F41+F43 -> 2272254 | G45: =G39+G41+G43 -> 662787 | H45: =H39+H41+H43 -> 726590 | I45: =I39+I41+I43 -> 765546.73 | ... P45: =P39+P41+P43 -> 3910738.3
A47: Income from Operations | B47: =B36-B45 -> 176048 | C47: =C36-C45 -> 269317 | D47: =D36-D45 -> 393256 | E47: =E36-E45 -> 575394 | F47: =F36-F45 -> 1414015 | G47: =G36-G45 -> 753998 | H47: =H36-H45 -> 912004 | I47: =I36-I45 -> 990000.23 | ... P47: =P36-P45 -> 6034015.1
...

Sheet Assumptions
A1: PLTR Model — Assumptions
A2: Blue font = hardcoded forecast driver (Q3'26E–Q4'27E). Black font (cols B–H, K, P) = actual/implied ratio computed from the Income Statement tab — shown for context, not an input.
A3: Growth assumptions are YoY (applied to the same quarter one year prior) to preserve seasonality; ratio assumptions are % of Total Revenue unless noted.
B5: Q1'25A | C5: Q2'25A | D5: Q3'25A | E5: Q4'25A | F5: FY2025A | G5: Q1'26A | H5: Q2'26A | I5: Q3'26E | J5: Q4'26E | K5: FY2026E | L5: Q1'27E | M5: Q2'27E | N5: Q3'27E | O5: Q4'27E | P5: FY2027E
A7: Revenue Growth Assumptions (YoY %, same quarter prior year)
A8: US Government Revenue — YoY Growth % | G8: ='Income Statement'!G8/'Income Statement'!B8-1 -> 0.84182306 | H8: ='Income Statement'!H8/'Income Statement'!C8-1 -> 0.89861535 | I8: 0.65 | J8: 0.55 | K8: ='Income Statement'!K8/'Income Statement'!F8-1 -> 0.71494798 | L8: 0.45 | M8: 0.4 | N8: 0.35 | O8: 0.3 | P8: ='Income Statement'!P8/'Income Statement'!K8-1 -> 0.3704234
A9: US Commercial Revenue — YoY Growth % | G9: ='Income Statement'!G9/'Income Statement'!B9-1 -> 1.3333333 | H9: ='Income Statement'!H9/'Income Statement'!C9-1 -> 1.4926591 | I9: 1 | J9: 0.85 | K9: ='Income Statement'!K9/'Income Statement'!F9-1 -> 1.1091436 | L9: 0.7 | M9: 0.6 | N9: 0.52 | O9: 0.45 | P9: ='Income Statement'!P9/'Income Statement'!K9-1 -> 0.55318187
A10: International Government Revenue — YoY Growth % | G10: ='Income Statement'!G10/'Income Statement'!B10-1 -> 0.50408466 | H10: ='Income Statement'!H10/'Income Statement'!C10-1 -> 0.42676324 | I10: 0.42 | J10: 0.38 | K10: ='Income Statement'!K10/'Income Statement'!F10-1 -> 0.42740895 | L10: 0.34 | M10: 0.3 | N10: 0.27 | O10: 0.24 | P10: ='Income Statement'!P10/'Income Statement'!K10-1 -> 0.28385237
A11: International Commercial Revenue — YoY Growth % | G11: ='Income Statement'!G11/'Income Statement'!B11-1 -> 0.26274209 | H11: ='Income Statement'!H11/'Income Statement'!C11-1 -> 0.25807481 | I11: 0.32 | J11: 0.34 | K11: ='Income Statement'!K11/'Income Statement'!F11-1 -> 0.29753316 | L11: 0.35 | M11: 0.35 | N11: 0.33 | O11: 0.3 | P11: ='Income Statement'!P11/'Income Statement'!K11-1 -> 0.33047256
A13: Margin & Opex Ratio Assumptions
A14: Gross Margin % | B14: ='Income Statement'!B36/'Income Statement'!B34 -> 0.80430048 | C14: ='Income Statement'!C36/'Income Statement'!C34 -> 0.80777665 | D14: ='Income Statement'!D36/'Income Statement'!D34 -> 0.82447853 | E14: ='Income Statement'!E36/'Income Statement'!E34 -> 0.84648444 | F14: ='Income Statement'!F36/'Income Statement'!F34 -> 0.82366517 | G14: ='Income Statement'!G36/'Income Statement'!G34 -> 0.86781805 | H14: ='Income Statement'!H36/'Income Statement'!H34 -> 0.84661559 | I14: 0.876 | J14: 0.88 | K14: ='Income Statement'!K36/'Income Statement'!K34 -> 0.86820197 | L14: 0.883 | M14: 0.886 | N14: 0.888 | O14: 0.89 | P14: ='Income Statement'!P36/'Income Statement'!P34 -> 0.88693776
A15: Sales & Marketing — % of Revenue | B15: ='Income Statement'!B39/'Income Statement'!B34 -> 0.26736173 | C15: ='Income Statement'!C39/'Income Statement'!C34 -> 0.24289004 | D15: ='Income Statement'!D39/'Income Statement'!D34 -> 0.23252719 | E15: ='Income Statement'!E39/'Income Statement'!E34 -> 0.21476085 | F15: ='Income Statement'!F39/'Income Statement'!F34 -> 0.23614607 | G15: ='Income Statement'!G39/'Income Statement'!G34 -> 0.19553064 | H15: ='Income Statement'!H39/'Income Statement'!H34 -> 0.17541013 | I15: 0.185 | J15: 0.18 | K15: ='Income Statement'!K39/'Income Statement'!K34 -> 0.18337825 | L15: 0.175 | M15: 0.17 | N15: 0.165 | O15: 0.16 | P15: ='Income Statement'!P39/'Income Statement'!P34 -> 0.16710282
A16: Research & Development — % of Revenue | B16: ='Income Statement'!B41/'Income Statement'!B34 -> 0.1526144 | C16: ='Income Statement'!C41/'Income Statement'!C34 -> 0.13454558 | D16: ='Income Statement'!D41/'Income Statement'!D34 -> 0.12208278 | E16: ='Income Statement'!E41/'Income Statement'!E34 -> 0.10204279 | F16: ='Income Statement'!F41/'Income Statement'!F34 -> 0.12460814 | G16: ='Income Statement'!G41/'Income Statement'!G34 -> 0.098605094 | H16: ='Income Statement'!H41/'Income Statement'!H34 -> 0.099466071 | I16: 0.092 | J16: 0.09 | K16: ='Income Statement'!K41/'Income Statement'!K34 -> 0.094638929 | L16: 0.088 | M16: 0.086 | N16: 0.084 | O16: 0.082 | P16: ='Income Statement'!P41/'Income Statement'!P34 -> 0.084841126
A17: General & Administrative — % of Revenue | B17: ='Income Statement'!B43/'Income Statement'!B34 -> 0.18514236 | C17: ='Income Statement'!C43/'Income Statement'!C34 -> 0.16201603 | D17: ='Income Statement'!D43/'Income Statement'!D34 -> 0.13690889 | E17: ='Income Statement'!E43/'Income Statement'!E34 -> 0.12067228 | F17: ='Income Statement'!F43/'Income Statement'!F34 -> 0.14696144 | G17: ='Income Statement'!G43/'Income Statement'!G34 -> 0.11183872 | H17: ='Income Statement'!H43/'Income Statement'!H34 -> 0.10053248 | I17: 0.105 | J17: 0.102 | K17: ='Income Statement'!K43/'Income Statement'!K34 -> 0.10445278 | L17: 0.1 | M17: 0.098 | N17: 0.096 | O17: 0.094 | P17: ='Income Statement'!P43/'Income Statement'!P34 -> 0.096841126
A18: Other Income, Net — % of Revenue | B18: ='Income Statement'!B49/'Income Statement'!B34 -> 0.05347936 | C18: ='Income Statement'!C49/'Income Statement'!C34 -> 0.062619496 | D18: ='Income Statement'!D49/'Income Statement'!D34 -> 0.073868081 | E18: ='Income Statement'!E49/'Income Statement'!E34 -> 0.032690457 | F18: ='Income Statement'!F49/'Income Statement'!F34 -> 0.054375139 | G18: ='Income Statement'!G49/'Income Statement'!G34 -> 0.082447876 | H18: ='Income Statement'!H49/'Income Statement'!H34 -> 0.087493748 | I18: 0.06 | J18: 0.055 | K18: ='Income Statement'!K49/'Income Statement'!K34 -> 0.070011942 | L18: 0.05 | M18: 0.047 | N18: 0.044 | O18: 0.04 | P18: ='Income Statement'!P49/'Income Statement'!P34 -> 0.044987157
A19: Stock-Based Compensation — % of Revenue (memo) | B19: ='Income Statement'!B61/'Income Statement'!B34 -> 0.17575168 | C19: ='Income Statement'!C61/'Income Statement'!C34 -> 0.15938177 | D19: ='Income Statement'!D61/'Income Statement'!D34 -> 0.14589719 | E19: ='Income Statement'!E61/'Income Statement'!E34 -> 0.13961098 | F19: ='Income Statement'!F61/'Income Statement'!F34 -> 0.1528413 | G19: ='Income Statement'!G61/'Income Statement'!G34 -> 0.1234804 | H19: ='Income Statement'!H61/'Income Statement'!H34 -> 0.13702606 | I19: 0.117 | J19: 0.114 | K19: ='Income Statement'!K61/'Income Statement'!K34 -> 0.12242348 | L19: 0.11 | M19: 0.107 | N19: 0.104 | O19: 0.101 | P19: ='Income Statement'!P61/'Income Statement'!P34 -> 0.10526169
A21: Tax & Capitalization Assumptions
A22: Effective Tax Rate % (of Pretax Income) | B22: ='Income Statement'!B51/'Income Statement'!B50 -> 0.025072095 | C22: ='Income Statement'!C51/'Income Statement'!C50 -> 0.010825847 | D22: ='Income Statement'!D51/'Income Statement'!D50 -> 0.0078105977 | E22: ='Income Statement'!E51/'Income Statement'!E50 -> 0.015732648 | F22: ='Income Statement'!F51/'Income Statement'!F50 -> 0.013710896 | G22: ='Income Statement'!G51/'Income Statement'!G50 -> 0.013728321 | H22: ='Income Statement'!H51/'Income Statement'!H50 -> 0.014225802 | I22: 0.015 | J22: 0.015 | K22: ='Income Statement'!K51/'Income Statement'!K50 -> 0.01454861 | L22: 0.015 | M22: 0.015 | N22: 0.015 | O22: 0.015 | P22: ='Income Statement'!P51/'Income Statement'!P50 -> 0.015
A23: Net Income Attributable to NCI — % of Net Income | B23: ='Income Statement'!B54/'Income Statement'!B53 -> 0.016930235 | C23: ='Income Statement'!C54/'Income Statement'!C53 -> 0.0056152076 | D23: ='Income Statement'!D54/'Income Statement'!D53 -> 0.0024100783 | E23: ='Income Statement'!E54/'Income Statement'!E53 -> 0.0047922931 | F23: ='Income Statement'!F54/'Income Statement'!F53 -> 0.0058795677 | G23: ='Income Statement'!G54/'Income Statement'!G53 -> 0.0067035447 | H23: ='Income Statement'!H54/'Income Statement'!H53 -> 0.0038200236 | I23: 0.005 | J23: 0.005 | K23: ='Income Statement'!K54/'Income Statement'!K53 -> 0.0050547609 | L23: 0.005 | M23: 0.005 | N23: 0.005 | O23: 0.005 | P23: ='Income Statement'!P54/'Income Statement'!P53 -> 0.005
A24: Diluted Share Count — QoQ Growth % | C24: ='Income Statement'!C58/'Income Statement'!B58-1 -> 0.0039540617 | D24: ='Income Statement'!D58/'Income Statement'!C58-1 -> 0.0031780256 | E24: ='Income Statement'!E58/'Income Statement'!D58-1 -> 0.00094902602 | G24: ='Income Statement'!G58/'Income Statement'!E58-1 -> -0.00099980688 | H24: ='Income Statement'!H58/'Income Statement'!G58-1 -> -0.00086739242 | I24: 0.002 | J24: 0.002 | K24: ='Income Statement'!K58/'Income Statement'!F58-1 -> 0.0031328995 | L24: 0.002 | M24: 0.002 | N24: 0.002 | O24: 0.002 | P24: ='Income Statement'!P58/'Income Statement'!K58-1 -> 0.0073034861

Sheet Sources
A1: Sources
A2: All FY2025 and Q1 FY2026 actuals in this model are drawn directly from Palantir Technologies Inc.'s SEC filings (Form 10-Q, Form 10-K, and Form 8-K earnings press releases). Figures tie exactly to reported GAAP totals; where a quarterly US Government / US Commercial split is disclosed only as a press-release rounded figure (nearest $1M), the corresponding International Government / International Commercial cell is derived by subtraction from the exact 10-Q/10-K segment total, as noted. Q4 FY2025 US and segment totals are derived as the FY2025 10-K exact annual figure less the sum of the exact Q1–Q3 FY2025 10-Q figures.
A4: Document | B4: Filed | C4: Period Covered | D4: URL
A5: Q1 2025 Earnings Press Release (Exhibit 99.1 to Form 8-K) | B5: 2025-05-05 | C5: Q1 FY2025 (ended 3/31/2025) | D5: https://www.sec.gov/Archives/edgar/data/1321655/000132165525000063/a2025q1ex991pressrelease.htm
A6: Form 10-Q | B6: 2025-05-06 | C6: Q1 FY2025 (ended 3/31/2025) | D6: https://www.sec.gov/Archives/edgar/data/1321655/000132165525000066/pltr-20250331.htm
A7: Q2 2025 Earnings Press Release (Exhibit 99.1 to Form 8-K) | B7: 2025-08-04 | C7: Q2 FY2025 (ended 6/30/2025) | D7: https://www.sec.gov/Archives/edgar/data/1321655/000132165525000105/a2025q2ex991pressrelease.htm
A8: Form 10-Q | B8: 2025-08-04 | C8: Q2 FY2025 (ended 6/30/2025) | D8: https://www.sec.gov/Archives/edgar/data/1321655/000132165525000106/pltr-20250630.htm
A9: Q3 2025 Earnings Press Release (Exhibit 99.1 to Form 8-K) | B9: 2025-11-03 | C9: Q3 FY2025 (ended 9/30/2025) | D9: https://www.sec.gov/Archives/edgar/data/1321655/000132165525000130/a2025q3ex991earningsrelease.htm
A10: Form 10-Q | B10: 2025-11-04 | C10: Q3 FY2025 (ended 9/30/2025) | D10: https://www.sec.gov/Archives/edgar/data/1321655/000132165525000131/pltr-20250930.htm
A11: Q4 & FY2025 Earnings Press Release (Exhibit 99.1 to Form 8-K) | B11: 2026-02-02 | C11: Q4 & FY2025 (ended 12/31/2025) | D11: https://www.sec.gov/Archives/edgar/data/1321655/000132165526000004/a2025q4ex991earningsrelease.htm
A12: Form 10-K | B12: 2026-02-17 | C12: FY2025 (ended 12/31/2025) | D12: https://www.sec.gov/Archives/edgar/data/1321655/000132165526000011/pltr-20251231.htm
A13: Q1 2026 Earnings Press Release (Exhibit 99.1 to Form 8-K) | B13: 2026-05-04 | C13: Q1 FY2026 (ended 3/31/2026) | D13: https://www.sec.gov/Archives/edgar/data/1321655/000132165526000026/a2026q1ex991pressrelease.htm
A14: Form 10-Q | B14: 2026-05-05 | C14: Q1 FY2026 (ended 3/31/2026) | D14: https://www.sec.gov/Archives/edgar/data/1321655/000132165526000028/pltr-20260331.htm
A16: Forecast methodology
A17: • Q2 FY2026 revenue and margin assumptions are calibrated to Palantir's own Q2 FY2026 guidance ($1.797B–$1.801B revenue; $1.063B–$1.067B adjusted income from operations) and FY2026 guidance ($7.650B–$7.662B revenue, raised at the Q1 2026 release), both disclosed in the Q1 2026 earnings press release (source above).
A18: • Q3 FY2026–Q4 FY2027 have no company guidance; each segment's YoY growth rate is projected to decelerate gradually from its Q1/Q2 FY2026 pace — consistent with Palantir's realized deceleration curve through FY2025–FY2026 — and is applied to the same quarter one year prior (not compounded quarter-over-quarter) to preserve each segment's seasonal pattern.
A19: • Gross margin, opex ratios (S&M/R&D/G&A as % of revenue), and SBC % of revenue are extrapolated along their observed FY2025–Q1 FY2026 operating-leverage trend lines.
A20: • The effective tax rate is held near its FY2025 GAAP level (~1.4%) given Palantir's disclosed full valuation allowance against U.S./U.K. deferred tax assets (Form 10-K, Note on Income Taxes) — no valuation-allowance release is assumed.
A21: • Diluted share count is grown at a modest sequential rate consistent with the FY2025–Q1 FY2026 realized trend (~0.2%/quarter).
A22: • All forecast figures (Q2 FY2026–Q4 FY2027) are Gridpath-modeled estimates, not Palantir guidance or analyst consensus, except where a cell is explicitly calibrated to guidance as noted above.
