Workbook

Sheet Income Statement
A1: Apple Inc. (AAPL) — Income Statement: Actuals & Forecast, FY2026-FY2028
A2: $ in millions, except per-share amounts; share counts in millions. Apple’s fiscal year ends the last Saturday of September. Q1-Q3 FY2026 are reported actuals (filed 10-Q/8-K); Q4 FY2026 onward are forecast. See the Assumptions and Notes tabs for methodology and sources.
A4: Fiscal Period | B4: FY2024 | C4: Q1 FY25 | D4: Q2 FY25 | E4: Q3 FY25 | F4: Q4 FY25 | G4: FY2025 | H4: Q1 FY26 | I4: Q2 FY26 | J4: Q3 FY26 | K4: Q4 FY26 | L4: FY2026 | M4: Q1 FY27 | N4: Q2 FY27 | O4: Q3 FY27 | P4: Q4 FY27 | Q4: FY2027 | R4: Q1 FY28 | S4: Q2 FY28 | T4: Q3 FY28 | U4: Q4 FY28 | V4: FY2028
B5: Oct 2023 - Sep 2024 | C5: Oct-Dec 2024 | D5: Jan-Mar 2025 | E5: Apr-Jun 2025 | F5: Jul-Sep 2025 | G5: Full Fiscal Year | H5: Oct-Dec 2025 | I5: Jan-Mar 2026 | J5: Apr-Jun 2026 | K5: Jul-Sep 2026 | L5: Full Fiscal Year | M5: Oct-Dec 2026 | N5: Jan-Mar 2027 | O5: Apr-Jun 2027 | P5: Jul-Sep 2027 | Q5: Full Fiscal Year | R5: Oct-Dec 2027 | S5: Jan-Mar 2028 | T5: Apr-Jun 2028 | U5: Jul-Sep 2028 | V5: Full Fiscal Year
B6: Actual | C6: Actual | D6: Actual | E6: Actual | F6: Actual | G6: Actual | H6: Actual | I6: Actual | J6: Actual | K6: Forecast | L6: Actual + Fcst | M6: Forecast | N6: Forecast | O6: Forecast | P6: Forecast | Q6: Forecast | R6: Forecast | S6: Forecast | T6: Forecast | U6: Forecast | V6: Forecast
A8: Net Sales
A9: iPhone | B9: ='Historical Data'!B8 -> 201183 | C9: ='Historical Data'!C8 -> 69138 | D9: ='Historical Data'!D8 -> 46841 | E9: ='Historical Data'!E8 -> 44582 | F9: ='Historical Data'!F8 -> 49025 | G9: =SUM(C9,D9,E9,F9) -> 209586 | H9: ='Historical Data'!G8 -> 85269 | I9: ='Historical Data'!H8 -> 56994 | J9: ='Historical Data'!I8 -> 54252 | K9: =F9*(1+Assumptions!B9) -> 56378.75 | L9: =SUM(H9,I9,J9,K9) -> 252893.75 | M9: =H9*(1+Assumptions!C9) -> 92090.52 | N9: =I9*(1+Assumptions!D9) -> 60983.58 | O9: =J9*(1+Assumptions!E9) -> 57507.12 | P9: =K9*(1+Assumptions!F9) -> 59761.475 | Q9: =SUM(M9,N9,O9,P9) -> 270342.7 | R9: =M9*(1+Assumptions!G9) -> 96695.046 | S9: =N9*(1+Assumptions!H9) -> 64032.759 | T9: =O9*(1+Assumptions!I9) -> 60382.476 | U9: =P9*(1+Assumptions!J9) -> 62749.549 | V9: =SUM(R9,S9,T9,U9) -> 283859.83
A10: Mac | B10: ='Historical Data'!B9 -> 29984 | C10: ='Historical Data'!C9 -> 8987 | D10: ='Historical Data'!D9 -> 7949 | E10: ='Historical Data'!E9 -> 8046 | F10: ='Historical Data'!F9 -> 8726 | G10: =SUM(C10,D10,E10,F10) -> 33708 | H10: ='Historical Data'!G9 -> 8386 | I10: ='Historical Data'!H9 -> 8399 | J10: ='Historical Data'!I9 -> 10352 | K10: =F10*(1+Assumptions!B10) -> 9162.3 | L10: =SUM(H10,I10,J10,K10) -> 36299.3 | M10: =H10*(1+Assumptions!C10) -> 8805.3 | N10: =I10*(1+Assumptions!D10) -> 8818.95 | O10: =J10*(1+Assumptions!E10) -> 10869.6 | P10: =K10*(1+Assumptions!F10) -> 9620.415 | Q10: =SUM(M10,N10,O10,P10) -> 38114.265 | R10: =M10*(1+Assumptions!G10) -> 9157.512 | S10: =N10*(1+Assumptions!H10) -> 9171.708 | T10: =O10*(1+Assumptions!I10) -> 11304.384 | U10: =P10*(1+Assumptions!J10) -> 10005.232 | V10: =SUM(R10,S10,T10,U10) -> 39638.836
A11: iPad | B11: ='Historical Data'!B10 -> 26694 | C11: ='Historical Data'!C10 -> 8088 | D11: ='Historical Data'!D10 -> 6402 | E11: ='Historical Data'!E10 -> 6581 | F11: ='Historical Data'!F10 -> 6952 | G11: =SUM(C11,D11,E11,F11) -> 28023 | H11: ='Historical Data'!G10 -> 8595 | I11: ='Historical Data'!H10 -> 6914 | J11: ='Historical Data'!I10 -> 6191 | K11: =F11*(1+Assumptions!B11) -> 6395.84 | L11: =SUM(H11,I11,J11,K11) -> 28095.84 | M11: =H11*(1+Assumptions!C11) -> 8766.9 | N11: =I11*(1+Assumptions!D11) -> 7121.42 | O11: =J11*(1+Assumptions!E11) -> 6376.73 | P11: =K11*(1+Assumptions!F11) -> 6587.7152 | Q11: =SUM(M11,N11,O11,P11) -> 28852.765 | R11: =M11*(1+Assumptions!G11) -> 9029.907 | S11: =N11*(1+Assumptions!H11) -> 7335.0626 | T11: =O11*(1+Assumptions!I11) -> 6568.0319 | U11: =P11*(1+Assumptions!J11) -> 6785.3467 | V11: =SUM(R11,S11,T11,U11) -> 29718.348
A12: Wearables, Home and Accessories | B12: ='Historical Data'!B11 -> 37005 | C12: ='Historical Data'!C11 -> 11747 | D12: ='Historical Data'!D11 -> 7522 | E12: ='Historical Data'!E11 -> 7404 | F12: ='Historical Data'!F11 -> 9013 | G12: =SUM(C12,D12,E12,F12) -> 35686 | H12: ='Historical Data'!G11 -> 11493 | I12: ='Historical Data'!H11 -> 7901 | J12: ='Historical Data'!I11 -> 7883 | K12: =F12*(1+Assumptions!B12) -> 9373.52 | L12: =SUM(H12,I12,J12,K12) -> 36650.52 | M12: =H12*(1+Assumptions!C12) -> 11952.72 | N12: =I12*(1+Assumptions!D12) -> 8217.04 | O12: =J12*(1+Assumptions!E12) -> 8198.32 | P12: =K12*(1+Assumptions!F12) -> 9748.4608 | Q12: =SUM(M12,N12,O12,P12) -> 38116.541 | R12: =M12*(1+Assumptions!G12) -> 12311.302 | S12: =N12*(1+Assumptions!H12) -> 8463.5512 | T12: =O12*(1+Assumptions!I12) -> 8444.2696 | U12: =P12*(1+Assumptions!J12) -> 10040.915 | V12: =SUM(R12,S12,T12,U12) -> 39260.037
A13: Total Products | B13: =B9+B10+B11+B12 -> 294866 | C13: =C9+C10+C11+C12 -> 97960 | D13: =D9+D10+D11+D12 -> 68714 | E13: =E9+E10+E11+E12 -> 66613 | F13: =F9+F10+F11+F12 -> 73716 | G13: =G9+G10+G11+G12 -> 307003 | H13: =H9+H10+H11+H12 -> 113743 | I13: =I9+I10+I11+I12 -> 80208 | ... V13: =V9+V10+V11+V12 -> 392477.05
A14: Services | B14: ='Historical Data'!B12 -> 96169 | C14: ='Historical Data'!C12 -> 26340 | D14: ='Historical Data'!D12 -> 26645 | E14: ='Historical Data'!E12 -> 27423 | F14: ='Historical Data'!F12 -> 28750 | G14: =SUM(C14,D14,E14,F14) -> 109158 | H14: ='Historical Data'!G12 -> 30013 | I14: ='Historical Data'!H12 -> 30976 | J14: ='Historical Data'!I12 -> 30739 | K14: =F14*(1+Assumptions!B13) -> 32200 | L14: =SUM(H14,I14,J14,K14) -> 123928 | M14: =H14*(1+Assumptions!C13) -> 33914.69 | N14: =I14*(1+Assumptions!D13) -> 34693.12 | O14: =J14*(1+Assumptions!E13) -> 34427.68 | P14: =K14*(1+Assumptions!F13) -> 36064 | Q14: =SUM(M14,N14,O14,P14) -> 139099.49 | R14: =M14*(1+Assumptions!G13) -> 37645.306 | S14: =N14*(1+Assumptions!H13) -> 38509.363 | T14: =O14*(1+Assumptions!I13) -> 38214.725 | U14: =P14*(1+Assumptions!J13) -> 40031.04 | V14: =SUM(R14,S14,T14,U14) -> 154400.43
A15: Total Net Sales | B15: =B13+B14 -> 391035 | C15: =C13+C14 -> 124300 | D15: =D13+D14 -> 95359 | E15: =E13+E14 -> 94036 | F15: =F13+F14 -> 102466 | G15: =G13+G14 -> 416161 | H15: =H13+H14 -> 143756 | I15: =I13+I14 -> 111184 | ... V15: =V13+V14 -> 546877.48
A16: YoY % Growth — Total Net Sales | B16: n/a | C16: n/a | D16: n/a | E16: n/a | F16: n/a | G16: =G15/B15-1 -> 0.064255118 | H16: =H15/C15-1 -> 0.15652454 | I16: =I15/D15-1 -> 0.16595182 | J16: =J15/E15-1 -> 0.16356502 | K16: =K15/F15-1 -> 0.10778609 | L16: =L15/G15-1 -> 0.14827533 | M16: =M15/H15-1 -> 0.081903573 | N16: =N15/I15-1 -> 0.077799953 | ... V16: =V15/Q15-1 -> 0.062876791
A18: Cost of Sales
A19: Cost of Sales — Products | B19: ='Historical Data'!B13 -> 185233 | C19: ='Historical Data'!C13 -> 59447 | D19: ='Historical Data'!D13 -> 44030 | E19: ='Historical Data'!E13 -> 43620 | F19: ='Historical Data'!F13 -> 47019 | G19: =SUM(C19,D19,E19,F19) -> 194116 | H19: ='Historical Data'!G13 -> 67478 | I19: ='Historical Data'!H13 -> 49179 | J19: ='Historical Data'!I13 -> 47153 | K19: =K13*(1-Assumptions!B15) -> 51632.11 | L19: =SUM(H19,I19,J19,K19) -> 215442.11 | M19: =M13*(1-Assumptions!C15) -> 76617.727 | N19: =N13*(1-Assumptions!D15) -> 53638.824 | O19: =O13*(1-Assumptions!E15) -> 51844.856 | P19: =P13*(1-Assumptions!F15) -> 53573.791 | Q19: =SUM(M19,N19,O19,P19) -> 235675.2 | R19: =R13*(1-Assumptions!G15) -> 78860.135 | S19: =S13*(1-Assumptions!H15) -> 55181.91 | T19: =T13*(1-Assumptions!I15) -> 53319.984 | U19: =U13*(1-Assumptions!J15) -> 55092.341 | V19: =SUM(R19,S19,T19,U19) -> 242454.37
A20: Cost of Sales — Services | B20: ='Historical Data'!B14 -> 25119 | C20: ='Historical Data'!C14 -> 6578 | D20: ='Historical Data'!D14 -> 6462 | E20: ='Historical Data'!E14 -> 6698 | F20: ='Historical Data'!F14 -> 7106 | G20: =SUM(C20,D20,E20,F20) -> 26844 | H20: ='Historical Data'!G14 -> 7047 | I20: ='Historical Data'!H14 -> 7224 | J20: ='Historical Data'!I14 -> 7494 | K20: =K14*(1-Assumptions!B16) -> 7889 | L20: =SUM(H20,I20,J20,K20) -> 29654 | M20: =M14*(1-Assumptions!C16) -> 8139.5256 | N20: =N14*(1-Assumptions!D16) -> 8326.3488 | O20: =O14*(1-Assumptions!E16) -> 8090.5048 | P20: =P14*(1-Assumptions!F16) -> 8475.04 | Q20: =SUM(M20,N20,O20,P20) -> 33031.419 | R20: =R14*(1-Assumptions!G16) -> 8658.4204 | S20: =S14*(1-Assumptions!H16) -> 8857.1535 | T20: =T14*(1-Assumptions!I16) -> 8598.3131 | U20: =U14*(1-Assumptions!J16) -> 9006.984 | V20: =SUM(R20,S20,T20,U20) -> 35120.871
A21: Total Cost of Sales | B21: =B19+B20 -> 210352 | C21: =C19+C20 -> 66025 | D21: =D19+D20 -> 50492 | E21: =E19+E20 -> 50318 | F21: =F19+F20 -> 54125 | G21: =G19+G20 -> 220960 | H21: =H19+H20 -> 74525 | I21: =I19+I20 -> 56403 | ... V21: =V19+V20 -> 277575.24
A23: Gross Margin
A24: Gross Margin ($) | B24: =B15-B21 -> 180683 | C24: =C15-C21 -> 58275 | D24: =D15-D21 -> 44867 | E24: =E15-E21 -> 43718 | F24: =F15-F21 -> 48341 | G24: =G15-G21 -> 195201 | H24: =H15-H21 -> 69231 | I24: =I15-I21 -> 54781 | ... V24: =V15-V21 -> 269302.24
A25: Gross Margin % of Net Sales | B25: =B24/B15 -> 0.4620635 | C25: =C24/C15 -> 0.46882542 | D25: =D24/D15 -> 0.47050619 | E25: =E24/E15 -> 0.46490706 | F25: =F24/F15 -> 0.471776 | G25: =G24/G15 -> 0.46905164 | H25: =H24/H15 -> 0.48158686 | I25: =I24/I15 -> 0.49270579 | ... V25: =V24/V15 -> 0.49243615
A26: memo: Products Gross Margin % | B26: =(B13-B19)/B13 -> 0.37180618 | C26: =(C13-C19)/C13 -> 0.39315027 | D26: =(D13-D19)/D13 -> 0.3592281 | E26: =(E13-E19)/E13 -> 0.34517286 | F26: =(F13-F19)/F13 -> 0.36216018 | G26: =(G13-G19)/G13 -> 0.3677065 | H26: =(H13-H19)/H13 -> 0.40675031 | I26: =(I13-I19)/I13 -> 0.38685667 | ... V26: =(V13-V19)/V13 -> 0.38224574
A27: memo: Services Gross Margin % | B27: =(B14-B20)/B14 -> 0.73880356 | C27: =(C14-C20)/C14 -> 0.75026576 | D27: =(D14-D20)/D14 -> 0.75747795 | E27: =(E14-E20)/E14 -> 0.75575247 | F27: =(F14-F20)/F14 -> 0.75283478 | G27: =(G14-G20)/G14 -> 0.75408124 | H27: =(H14-H20)/H14 -> 0.76520175 | I27: =(I14-I20)/I14 -> 0.76678719 | ... V27: =(V14-V20)/V14 -> 0.77253386
A29: Operating Expenses
A30: Research and Development | B30: ='Historical Data'!B15 -> 31370 | C30: ='Historical Data'!C15 -> 8268 | D30: ='Historical Data'!D15 -> 8550 | E30: ='Historical Data'!E15 -> 8866 | F30: ='Historical Data'!F15 -> 8866 | G30: =SUM(C30,D30,E30,F30) -> 34550 | H30: ='Historical Data'!G15 -> 10887 | I30: ='Historical Data'!H15 -> 11419 | J30: ='Historical Data'!I15 -> 11729 | K30: =K15*Assumptions!B18 -> 11237.531 | L30: =SUM(H30,I30,J30,K30) -> 45272.531 | M30: =M15*Assumptions!C18 -> 11820.29 | N30: =N15*Assumptions!D18 -> 12103.245 | O30: =O15*Assumptions!E18 -> 12324.842 | P30: =P15*Assumptions!F18 -> 11812.86 | Q30: =SUM(M30,N30,O30,P30) -> 48061.238 | R30: =R15*Assumptions!G18 -> 12198.091 | S30: =S15*Assumptions!H18 -> 12623.732 | T30: =T15*Assumptions!I18 -> 12866.13 | U30: =U15*Assumptions!J18 -> 12313.148 | V30: =SUM(R30,S30,T30,U30) -> 50001.101
A31: Selling, General and Administrative | B31: ='Historical Data'!B16 -> 26097 | C31: ='Historical Data'!C16 -> 7175 | D31: ='Historical Data'!D16 -> 6728 | E31: ='Historical Data'!E16 -> 6650 | F31: ='Historical Data'!F16 -> 7048 | G31: =SUM(C31,D31,E31,F31) -> 27601 | H31: ='Historical Data'!G16 -> 7492 | I31: ='Historical Data'!H16 -> 7477 | J31: ='Historical Data'!I16 -> 7346 | K31: =K15*Assumptions!B19 -> 7378.1766 | L31: =SUM(H31,I31,J31,K31) -> 29693.177 | M31: =M15*Assumptions!C19 -> 7932.0366 | N31: =N15*Assumptions!D19 -> 7909.0513 | O31: =O15*Assumptions!E19 -> 7747.0437 | P31: =P15*Assumptions!F19 -> 7794.0522 | Q31: =SUM(M31,N31,O31,P31) -> 31382.184 | R31: =R15*Assumptions!G19 -> 8241.9536 | S31: =S15*Assumptions!H19 -> 8288.3089 | T31: =T15*Assumptions!I19 -> 8119.4026 | U31: =U15*Assumptions!J19 -> 8165.5611 | V31: =SUM(R31,S31,T31,U31) -> 32815.226
A32: Total Operating Expenses | B32: =B30+B31 -> 57467 | C32: =C30+C31 -> 15443 | D32: =D30+D31 -> 15278 | E32: =E30+E31 -> 15516 | F32: =F30+F31 -> 15914 | G32: =G30+G31 -> 62151 | H32: =H30+H31 -> 18379 | I32: =I30+I31 -> 18896 | ... V32: =V30+V31 -> 82816.328
A33: memo: R&D % of Net Sales | B33: =B30/B15 -> 0.080222998 | C33: =C30/C15 -> 0.066516492 | D33: =D30/D15 -> 0.089661175 | E33: =E30/E15 -> 0.094283041 | F33: =F30/F15 -> 0.086526262 | G33: =G30/G15 -> 0.083020754 | H33: =H30/H15 -> 0.075732491 | I33: =I30/I15 -> 0.10270363 | ... V33: =V30/V15 -> 0.09143017
A34: memo: SG&A % of Net Sales | B34: =B31/B15 -> 0.066738272 | C34: =C31/C15 -> 0.05772325 | D34: =D31/D15 -> 0.070554431 | E34: =E31/E15 -> 0.070717598 | F34: =F31/F15 -> 0.068783792 | G34: =G31/G15 -> 0.066322889 | H34: =H31/H15 -> 0.052116086 | I34: =I31/I15 -> 0.067248885 | ... V34: =V31/V15 -> 0.060004713
A36: Operating Income | B36: =B24-B32 -> 123216 | C36: =C24-C32 -> 42832 | D36: =D24-D32 -> 29589 | E36: =E24-E32 -> 28202 | F36: =F24-F32 -> 32427 | G36: =G24-G32 -> 133050 | H36: =H24-H32 -> 50852 | I36: =I24-I32 -> 35885 | ... V36: =V24-V32 -> 186485.92
A37: Operating Margin % | B37: =B36/B15 -> 0.31510223 | C37: =C36/C15 -> 0.34458568 | D37: =D36/D15 -> 0.31029059 | E37: =E36/E15 -> 0.29990642 | F37: =F36/F15 -> 0.31646595 | G37: =G36/G15 -> 0.319708 | H37: =H36/H15 -> 0.35373828 | I37: =I36/I15 -> 0.32275327 | ... V37: =V36/V15 -> 0.34100127
A39: Non-Operating Items & Net Income
A40: Other Income/(Expense), net | B40: ='Historical Data'!B17 -> 269 | C40: ='Historical Data'!C17 -> -248 | D40: ='Historical Data'!D17 -> -279 | E40: ='Historical Data'!E17 -> -171 | F40: ='Historical Data'!F17 -> 377 | G40: =SUM(C40,D40,E40,F40) -> -321 | H40: ='Historical Data'!G17 -> 150 | I40: ='Historical Data'!H17 -> -52 | J40: ='Historical Data'!I17 -> 572 | K40: =K15*Assumptions!B20 -> 340.53123 | L40: =SUM(H40,I40,J40,K40) -> 1010.5312 | M40: =M15*Assumptions!C20 -> 155.53013 | N40: =N15*Assumptions!D20 -> -119.83411 | O40: =O15*Assumptions!E20 -> 469.5178 | P40: =P15*Assumptions!F20 -> 365.3462 | Q40: =SUM(M40,N40,O40,P40) -> 870.56002 | R40: =R15*Assumptions!G20 -> 164.83907 | S40: =S15*Assumptions!H20 -> -127.51244 | T40: =T15*Assumptions!I20 -> 499.65555 | U40: =U15*Assumptions!J20 -> 388.83624 | V40: =SUM(R40,S40,T40,U40) -> 925.81842
A41: Income Before Provision for Income Taxes | B41: =B36+B40 -> 123485 | C41: =C36+C40 -> 42584 | D41: =D36+D40 -> 29310 | E41: =E36+E40 -> 28031 | F41: =F36+F40 -> 32804 | G41: =G36+G40 -> 132729 | H41: =H36+H40 -> 51002 | I41: =I36+I40 -> 35833 | ... V41: =V36+V40 -> 187411.73
A42: Provision for Income Taxes | B42: ='Historical Data'!B18 -> 29749 | C42: ='Historical Data'!C18 -> 6254 | D42: ='Historical Data'!D18 -> 4530 | E42: ='Historical Data'!E18 -> 4597 | F42: ='Historical Data'!F18 -> 5338 | G42: =SUM(C42,D42,E42,F42) -> 20719 | H42: ='Historical Data'!G18 -> 8905 | I42: ='Historical Data'!H18 -> 6255 | J42: ='Historical Data'!I18 -> 6478 | K42: =K41*Assumptions!B21 -> 6357.114 | L42: =SUM(H42,I42,J42,K42) -> 27995.114 | M42: =M41*Assumptions!C21 -> 9058.1663 | N42: =N41*Assumptions!D21 -> 6679.4148 | O42: =O41*Assumptions!E21 -> 6697.9846 | P42: =P41*Assumptions!F21 -> 7167.0253 | Q42: =SUM(M42,N42,O42,P42) -> 29602.591 | R42: =R41*Assumptions!G21 -> 10097.02 | S42: =S41*Assumptions!H21 -> 7510.7874 | T42: =T41*Assumptions!I21 -> 7524.2189 | U42: =U41*Assumptions!J21 -> 8039.8505 | V42: =SUM(R42,S42,T42,U42) -> 33171.877
A43: Effective Tax Rate % | B43: =B42/B41 -> 0.24091185 | C43: =C42/C41 -> 0.14686267 | D43: =D42/D41 -> 0.15455476 | E43: =E42/E41 -> 0.163997 | F43: =F42/F41 -> 0.16272406 | G43: =G42/G41 -> 0.15610002 | H43: =H42/H41 -> 0.174601 | I43: =I42/I41 -> 0.17455976 | ... V43: =V42/V41 -> 0.177
A44: Net Income | B44: =B41-B42 -> 93736 | C44: =C41-C42 -> 36330 | D44: =D41-D42 -> 24780 | E44: =E41-E42 -> 23434 | F44: =F41-F42 -> 27466 | G44: =G41-G42 -> 112010 | H44: =H41-H42 -> 42097 | I44: =I41-I42 -> 29578 | ... V44: =V41-V42 -> 154239.86
A45: Net Margin % | B45: =B44/B15 -> 0.23971256 | C45: =C44/C15 -> 0.29227675 | D45: =D44/D15 -> 0.25986011 | E45: =E44/E15 -> 0.24920243 | F45: =F44/F15 -> 0.26804989 | G45: =G44/G15 -> 0.26915064 | H45: =H44/H15 -> 0.29283647 | I45: =I44/I15 -> 0.26602749 | ... V45: =V44/V15 -> 0.28203731
A47: Per Share Data
A48: Earnings Per Share — Basic | B48: =B44/B50 -> 6.1090541 | C48: =C44/C50 -> 2.4088758 | D48: =D44/D50 -> 1.652652 | E48: =E44/E50 -> 1.5724471 | F48: =F44/F50 -> 1.8538934 | G48: =G44/G50 -> 7.4930596 | H48: =H44/H50 -> 2.8543904 | I48: =I44/I50 -> 2.0157732 | ... V48: =V44/V50 -> 10.844974
...

Sheet Assumptions
A1: Apple Inc. — Forecast Assumptions
A2: All forecast formulas in the Income Statement tab reference these cells — change a value here to flow it through the entire model.
A3: Q4 FY26 is grounded in management guidance from the FY26 Q3 earnings call (Jul 30, 2026): total revenue +9% to +11% YoY, gross margin 47%-48%, iPhone mid-teens YoY growth, Services growth similar to the June quarter. FY27-FY28 are illustrative model extrapolations (iPhone growth normalizing off the FY26 upgrade supercycle, continued Services strength, gradual margin expansion, stable opex ratios, ~17.7% effective tax rate, continued buybacks) and are NOT official Apple guidance.
A5: Fiscal Period | B5: Q4 FY26 | C5: Q1 FY27 | D5: Q2 FY27 | E5: Q3 FY27 | F5: Q4 FY27 | G5: Q1 FY28 | H5: Q2 FY28 | I5: Q3 FY28 | J5: Q4 FY28
B6: Jul-Sep 2026 | C6: Oct-Dec 2026 | D6: Jan-Mar 2027 | E6: Apr-Jun 2027 | F6: Jul-Sep 2027 | G6: Oct-Dec 2027 | H6: Jan-Mar 2028 | I6: Apr-Jun 2028 | J6: Jul-Sep 2028
B7: Forecast | C7: Forecast | D7: Forecast | E7: Forecast | F7: Forecast | G7: Forecast | H7: Forecast | I7: Forecast | J7: Forecast
A8: Revenue growth (YoY, applied to same fiscal quarter prior year)
A9: iPhone revenue YoY growth % | B9: 0.15 | C9: 0.08 | D9: 0.07 | E9: 0.06 | F9: 0.06 | G9: 0.05 | H9: 0.05 | I9: 0.05 | J9: 0.05
A10: Mac revenue YoY growth % | B10: 0.05 | C10: 0.05 | D10: 0.05 | E10: 0.05 | F10: 0.05 | G10: 0.04 | H10: 0.04 | I10: 0.04 | J10: 0.04
A11: iPad revenue YoY growth % | B11: -0.08 | C11: 0.02 | D11: 0.03 | E11: 0.03 | F11: 0.03 | G11: 0.03 | H11: 0.03 | I11: 0.03 | J11: 0.03
A12: Wearables, Home & Accessories YoY growth % | B12: 0.04 | C12: 0.04 | D12: 0.04 | E12: 0.04 | F12: 0.04 | G12: 0.03 | H12: 0.03 | I12: 0.03 | J12: 0.03
A13: Services revenue YoY growth % | B13: 0.12 | C13: 0.13 | D13: 0.12 | E13: 0.12 | F13: 0.12 | G13: 0.11 | H13: 0.11 | I13: 0.11 | J13: 0.11
A14: Margins
A15: Products gross margin % | B15: 0.365 | C15: 0.37 | D15: 0.37 | E15: 0.375 | F15: 0.375 | G15: 0.38 | H15: 0.38 | I15: 0.385 | J15: 0.385
A16: Services gross margin % | B16: 0.755 | C16: 0.76 | D16: 0.76 | E16: 0.765 | F16: 0.765 | G16: 0.77 | H16: 0.77 | I16: 0.775 | J16: 0.775
A17: Operating expenses & other (as % of Total Net Sales, except tax)
A18: R&D as % of Net Sales | B18: 0.099 | C18: 0.076 | D18: 0.101 | E18: 0.105 | F18: 0.097 | G18: 0.074 | H18: 0.099 | I18: 0.103 | J18: 0.095
A19: SG&A as % of Net Sales | B19: 0.065 | C19: 0.051 | D19: 0.066 | E19: 0.066 | F19: 0.064 | G19: 0.05 | H19: 0.065 | I19: 0.065 | J19: 0.063
A20: Other income/(expense) as % of Net Sales | B20: 0.003 | C20: 0.001 | D20: -0.001 | E20: 0.004 | F20: 0.003 | G20: 0.001 | H20: -0.001 | I20: 0.004 | J20: 0.003
A21: Effective tax rate % | B21: 0.178 | C21: 0.177 | D21: 0.177 | E21: 0.177 | F21: 0.177 | G21: 0.177 | H21: 0.177 | I21: 0.177 | J21: 0.177
A22: Capital allocation
A23: Diluted/basic share count, QoQ % change (buybacks) | B23: -0.004 | C23: -0.004 | D23: -0.004 | E23: -0.004 | F23: -0.004 | G23: -0.004 | H23: -0.004 | I23: -0.004 | J23: -0.004

Sheet Historical Data
A1: Apple Inc. — Historical Actuals
A2: $ in millions, except per-share amounts; share counts in millions. Source: SEC Form 8-K Exhibit 99.1 (Condensed Consolidated Statements of Operations) for each fiscal quarter; cross-checked to the FY2025 Form 10-K.
A4: Fiscal Period | B4: FY2024 | C4: Q1 FY25 | D4: Q2 FY25 | E4: Q3 FY25 | F4: Q4 FY25 | G4: Q1 FY26 | H4: Q2 FY26 | I4: Q3 FY26
B5: Oct 2023 - Sep 2024 | C5: Oct-Dec 2024 | D5: Jan-Mar 2025 | E5: Apr-Jun 2025 | F5: Jul-Sep 2025 | G5: Oct-Dec 2025 | H5: Jan-Mar 2026 | I5: Apr-Jun 2026
B6: Actual | C6: Actual | D6: Actual | E6: Actual | F6: Actual | G6: Actual | H6: Actual | I6: Actual
A7: Reported line items
A8: iPhone | B8: 201183 | C8: 69138 | D8: 46841 | E8: 44582 | F8: 49025 | G8: 85269 | H8: 56994 | I8: 54252
A9: Mac | B9: 29984 | C9: 8987 | D9: 7949 | E9: 8046 | F9: 8726 | G9: 8386 | H9: 8399 | I9: 10352
A10: iPad | B10: 26694 | C10: 8088 | D10: 6402 | E10: 6581 | F10: 6952 | G10: 8595 | H10: 6914 | I10: 6191
A11: Wearables, Home and Accessories | B11: 37005 | C11: 11747 | D11: 7522 | E11: 7404 | F11: 9013 | G11: 11493 | H11: 7901 | I11: 7883
A12: Services | B12: 96169 | C12: 26340 | D12: 26645 | E12: 27423 | F12: 28750 | G12: 30013 | H12: 30976 | I12: 30739
A13: Cost of Sales — Products | B13: 185233 | C13: 59447 | D13: 44030 | E13: 43620 | F13: 47019 | G13: 67478 | H13: 49179 | I13: 47153
A14: Cost of Sales — Services | B14: 25119 | C14: 6578 | D14: 6462 | E14: 6698 | F14: 7106 | G14: 7047 | H14: 7224 | I14: 7494
A15: Research and Development | B15: 31370 | C15: 8268 | D15: 8550 | E15: 8866 | F15: 8866 | G15: 10887 | H15: 11419 | I15: 11729
A16: Selling, General and Administrative | B16: 26097 | C16: 7175 | D16: 6728 | E16: 6650 | F16: 7048 | G16: 7492 | H16: 7477 | I16: 7346
A17: Other Income/(Expense), net | B17: 269 | C17: -248 | D17: -279 | E17: -171 | F17: 377 | G17: 150 | H17: -52 | I17: 572
A18: Provision for Income Taxes | B18: 29749 | C18: 6254 | D18: 4530 | E18: 4597 | F18: 5338 | G18: 8905 | H18: 6255 | I18: 6478
A19: Weighted-Avg Shares Outstanding — Basic | B19: 15343.783 | C19: 15081.724 | D19: 14994.082 | E19: 14902.886 | F19: 14815.307 | G19: 14748.158 | H19: 14673.278 | I19: 14656.11
A20: Weighted-Avg Shares Outstanding — Diluted | B20: 15408.095 | C20: 15150.865 | D20: 15056.133 | E20: 14948.179 | F20: 14863.609 | G20: 14810.356 | H20: 14725.873 | I20: 14714.676

Sheet Notes & Sources
A1: Apple Inc. (AAPL) — Income Statement Forecast: Methodology & Sources
A3: Scope
A4: Quarterly and annual GAAP income statement, fiscal years 2026-2028 (Apple's fiscal year ends the last Saturday of September). As of this model's build date, Apple had reported actual results through fiscal Q3 2026 (quarter ended June 27, 2026); Q4 FY2026 through Q4 FY2028 are forecast.
A6: Structure
A7: - "Historical Data": raw reported actuals (blue font = hardcoded source data), FY2024 annual and FY2025 Q1-Q4 / FY2026 Q1-Q3 quarterly. - "Assumptions": editable forecast drivers (blue font) for every forecast quarter (Q4 FY26 - Q4 FY28). Change any cell here and the entire model recalculates. - "Income Statement": the full model. Historical columns pull from Historical Data; forecast columns are built up from the Assumptions drivers; annual columns SUM (or AVERAGE, for share counts) the four fiscal quarters. Every cell is a live formula.
A9: Forecast methodology
A10: - Revenue is built bottom-up by product/service category (iPhone, Mac, iPad, Wearables/Home/Accessories, Services), matching Apple's reported disclosure. Each forecast quarter grows off the SAME FISCAL QUARTER one year prior by an assumed YoY growth rate, which captures seasonality (e.g. the December quarter is always Apple's largest) without needing separate seasonal indices. - Cost of sales is derived from assumed Products and Services gross margin percentages applied to their respective forecast revenue. - R&D and SG&A are forecast as a percentage of Total Net Sales, calibrated to each quarter's recent seasonal pattern (opex ratios are structurally higher in the seasonally smaller March/June quarters). - Other Income/(Expense) is forecast as a small percentage of revenue, consistent with its recent small and mixed-sign contribution. - Tax is Income Before Taxes multiplied by an assumed effective tax rate. - Basic and diluted share counts roll forward sequentially (each quarter vs. the immediately prior quarter, not the prior year) at an assumed rate reflecting continued buybacks.
A12: Key assumptions and why
A13: - Q4 FY2026 is grounded in management's guidance from the FY26 Q3 earnings call (July 30, 2026): total revenue growth of +9% to +11% YoY, gross margin of 47%-48% (including a ~1pt tariff-refund benefit), iPhone growth in the mid-teens YoY, and Services growth similar to the June quarter's pace, against a backdrop of intensifying supply constraints on iPhone, Mac and iPad. - FY2027-FY2028 have NO official company guidance. They are modeled extrapolations: iPhone growth normalizing from the FY2026 "supercycle" (iPhone 17 demand, tariff-refund tailwinds) toward a more typical mid-single-digit pace; Services continuing as Apple's structural growth engine at low-double-digit growth; gradual gross-margin expansion in both Products and Services; a stable ~17.7% effective tax rate consistent with the step-up observed through FY2026 (vs. ~15.6% in FY2025); and continued share buybacks (Apple authorized an incremental $100B repurchase program in fiscal Q2 2026). - These are reasonable, internally consistent planning assumptions — not a Wall Street consensus estimate or Apple guidance. Treat the FY2027-FY2028 columns as illustrative and revisit the Assumptions tab as new information (guidance, macro, category trends) becomes available.
A15: Primary sources
A16: - Apple Inc. Form 8-K, Exhibit 99.1 (Condensed Consolidated Statements of Operations), each fiscal quarter FY2025 Q1 through FY2026 Q3, filed with the SEC (sec.gov/cgi-bin/browse-edgar?action=getcompany&CIK=0000320193). - Apple Inc. Form 10-K for fiscal year ended September 27, 2025. - Apple FY2026 Q3 earnings call and press release (apple.com/newsroom), July 30, 2026, for Q4 FY2026 guidance.
A18: Caveats
A19: This is a planning model, not investment advice. Actual results will differ from forecast columns; sensitivity to FX, tariffs, supply constraints, new product timing, and macro demand is material. All $ figures are in millions except per-share amounts; share counts are in millions.
