Workbook

Sheet Summary & Growth
B2: Delivery Hero SE — Income Statement & Growth Model
B3: FY2021–FY2025 | EUR million unless noted | Blue = reported input, Black = formula. See 'Sources' tab for citations.
B5: Metric | C5: FY2021 | D5: FY2022 | E5: FY2023 | F5: FY2024 | G5: FY2025 | H5: CAGR '21–'25
B6: Gross Merchandise Value (GMV) | C6: 35400 | D6: 44600 | E6: 45275.2 | F6: 48754 | G6: =F6*(1+G8) -> 52654.32 | H6: =IFERROR((G6/C6)^(1/4)-1,"n/m") -> 0.10435242
B7: YoY growth % | D7: =D6/C6-1 -> 0.25988701 | E7: =E6/D6-1 -> 0.015139013 | F7: =F6/E6-1 -> 0.076836767 | G7: =G6/F6-1 -> 0.08 | H7: =AVERAGE(D7:F7) -> 0.1172876
B8: FY2025 GMV growth % (mgmt-reported, LfL) | G8: 0.08
B10: Total Segment Revenue (non-IFRS) | C10: 6600 | D10: 9600 | E10: 10463.2 | F10: 12796.4 | G10: =F10*(1+G12) -> 15483.644 | H10: =IFERROR((G10/C10)^(1/4)-1,"n/m") -> 0.23760573
B11: YoY growth % | D11: =D10/C10-1 -> 0.45454545 | E11: =E10/D10-1 -> 0.089916667 | F11: =F10/E10-1 -> 0.22299105 | G11: =G10/F10-1 -> 0.21 | H11: =AVERAGE(D11:F11) -> 0.25581773
B12: FY2025 Segment Revenue growth % (mgmt-reported, LfL) | G12: 0.21
B13: Take rate (Segment Revenue / GMV) | C13: =C10/C6 -> 0.18644068 | D13: =D10/D6 -> 0.21524664 | E13: =E10/E6 -> 0.23110224 | F13: =F10/F6 -> 0.26246872 | G13: =G10/G6 -> 0.29406218
B15: IFRS Revenue | C15: 5856 | D15: 8577 | E15: 9941.9 | F15: 12294.7 | G15: 14060 | H15: =(G15/C15)^(1/4)-1 -> 0.24478992
B16: YoY growth % | D16: =D15/C15-1 -> 0.46465164 | E16: =E15/D15-1 -> 0.1591349 | F16: =F15/E15-1 -> 0.23665497 | G16: =G15/F15-1 -> 0.14358219 | H16: =AVERAGE(D16:G16) -> 0.25100592
B18: Gross Profit | C18: 1258 | D18: 2232 | E18: 2972.7 | F18: 3329.2 | G18: 3433
B19: Gross margin % (of Revenue) | C19: =C18/C15 -> 0.2148224 | D19: =D18/D15 -> 0.26023085 | E19: =E18/E15 -> 0.29900723 | F19: =F18/F15 -> 0.27078335 | G19: =G18/G15 -> 0.24416785
B21: Adjusted EBITDA | C21: =C6*C22 -> -778.8 | D21: =D6*D22 -> -624.4 | E21: 253.6 | F21: 692.5 | G21: =F21*(1+G23) -> 900.25
B22: Adj. EBITDA / GMV margin % (2021–22 reported basis) | C22: -0.022 | D22: -0.014 | E22: =E21/E6 -> 0.0056013005 | F22: =F21/F6 -> 0.014203963 | G22: =G21/G6 -> 0.017097363
B23: FY2025 Adj. EBITDA growth % (reported: 'up 30%') | G23: 0.3
B24: YoY € change (loss narrowing / turning positive) | D24: =D21-C21 -> 154.4 | E24: =E21-D21 -> 878 | F24: =F21-E21 -> 438.9 | G24: =G21-F21 -> 207.75
B26: Net Result (attributable to shareholders) | C26: -1124 | D26: -3008 | E26: -2297.5 | F26: -882.4 | G26: -782.9
B27: Net margin % (of Revenue) | C27: =C26/C15 -> -0.19193989 | D27: =D26/D15 -> -0.35070537 | E27: =E26/E15 -> -0.23109265 | F27: =F26/F15 -> -0.071770763 | G27: =G26/G15 -> -0.055682788
B29: Diluted EPS (EUR) | C29: -4.57 | D29: -11.28 | E29: -8.57 | F29: -3.1 | G29: -2.62
B31: Note: FY2021–22 GMV/Segment Revenue are rounded per company disclosure; FY2023–24 figures are exact, audited (Delivery Hero Annual Report 2024). FY2025 GMV/Segment Revenue/Adj. EBITDA are modeled from FY2024 actuals using management-reported FY2025 like-for-like growth rates (blue input cells above); FY2025 IFRS P&L figures are reported actuals. See 'Sources' tab.

Sheet Segment Detail
B2: Segment Detail — GMV, Segment Revenue & Adjusted EBITDA by Region
B3: EUR million | Source: Delivery Hero Annual Report 2024, 'Key Figures' (audited, exact) | Blue = reported input, Black = formula
B5: Segment / Metric | C5: FY2023 | D5: FY2024 | E5: YoY Δ | F5: YoY % | G5: % of Grp GMV FY24
B6: Europe
B7: GMV | C7: 7510 | D7: 8878.7 | E7: =D7-C7 -> 1368.7 | F7: =D7/C7-1 -> 0.18225033 | G7: =D7/$D$37 -> 0.18211224
B8: Segment Revenue | C8: 1522.4 | D8: 1891.9 | E8: =D8-C8 -> 369.5 | F8: =D8/C8-1 -> 0.24270888
B9: Adjusted EBITDA | C9: -168.2 | D9: -77 | E9: =D9-C9 -> 91.2 | F9: =IFERROR(D9/C9-1,"n/m") -> -0.54221165
B10: Adj. EBITDA / GMV margin % | C10: =C9/C7 -> -0.022396804 | D10: =D9/D7 -> -0.0086724408 | E10: =D10-C10 -> 0.013724363
B12: Americas
B13: GMV | C13: 2451.7 | D13: 3642 | E13: =D13-C13 -> 1190.3 | F13: =D13/C13-1 -> 0.48549986 | G13: =D13/$D$37 -> 0.074701563
B14: Segment Revenue | C14: 651 | D14: 939.6 | E14: =D14-C14 -> 288.6 | F14: =D14/C14-1 -> 0.44331797
B15: Adjusted EBITDA | C15: -49.9 | D15: 10.3 | E15: =D15-C15 -> 60.2 | F15: =IFERROR(D15/C15-1,"n/m") -> -1.2064128
B16: Adj. EBITDA / GMV margin % | C16: =C15/C13 -> -0.020353224 | D16: =D15/D13 -> 0.0028281164 | E16: =D16-C16 -> 0.023181341
B18: Asia
B19: GMV | C19: 25354.2 | D19: 23407.4 | E19: =D19-C19 -> -1946.8 | F19: =D19/C19-1 -> -0.076784123 | G19: =D19/$D$37 -> 0.4801124
B20: Segment Revenue | C20: 3729.4 | D20: 4071.9 | E20: =D20-C20 -> 342.5 | F20: =D20/C20-1 -> 0.091837829
B21: Adjusted EBITDA | C21: 385 | D21: 385.1 | E21: =D21-C21 -> 0.1 | F21: =IFERROR(D21/C21-1,"n/m") -> 0.00025974026
B22: Adj. EBITDA / GMV margin % | C22: =C21/C19 -> 0.015184861 | D22: =D21/D19 -> 0.016452062 | E22: =D22-C22 -> 0.0012672013
B24: MENA
B25: GMV | C25: 9959.3 | D25: 12825.9 | E25: =D25-C25 -> 2866.6 | F25: =D25/C25-1 -> 0.28783147 | G25: =D25/$D$37 -> 0.2630738
B26: Segment Revenue | C26: 2700.8 | D26: 3527.8 | E26: =D26-C26 -> 827 | F26: =D26/C26-1 -> 0.30620557
B27: Adjusted EBITDA | C27: 304.6 | D27: 472.9 | E27: =D27-C27 -> 168.3 | F27: =IFERROR(D27/C27-1,"n/m") -> 0.55252791
B28: Adj. EBITDA / GMV margin % | C28: =C27/C25 -> 0.030584479 | D28: =D27/D25 -> 0.036870707 | E28: =D28-C28 -> 0.0062862281
B30: Integrated Verticals
B31: GMV | C31: 2224.4 | D31: 2904.7 | E31: =D31-C31 -> 680.3 | F31: =D31/C31-1 -> 0.30583528 | G31: =D31/$D$37 -> 0.059578701
B32: Segment Revenue | C32: 2126.1 | D32: 2709.8 | E32: =D32-C32 -> 583.7 | F32: =D32/C32-1 -> 0.27454024
B33: Adjusted EBITDA | C33: -217.9 | D33: -98.7 | E33: =D33-C33 -> 119.2 | F33: =IFERROR(D33/C33-1,"n/m") -> -0.54703993
B34: Adj. EBITDA / GMV margin % | C34: =C33/C31 -> -0.097959 | D34: =D33/D31 -> -0.033979413 | E34: =D34-C34 -> 0.063979588
B36: GROUP TOTAL
B37: GMV | C37: 45275.2 | D37: 48754 | E37: =D37-C37 -> 3478.8 | F37: =D37/C37-1 -> 0.076836767 | G37: 1
B38: Total Segment Revenue | C38: 10463.2 | D38: 12796.4 | E38: =D38-C38 -> 2333.2 | F38: =D38/C38-1 -> 0.22299105
B39: Adjusted EBITDA | C39: 253.6 | D39: 692.5 | E39: =D39-C39 -> 438.9 | F39: =D39/C39-1 -> 1.7306782
B40: Adj. EBITDA / GMV margin % | C40: =C39/C37 -> 0.0056013005 | D40: =D39/D37 -> 0.014203963
B43: Note: MENA's own delivery/platform GMV is included within the regional platform segments; Integrated Verticals GMV is shown for illustrative purposes only, so segment GMV above does not sum arithmetically to Group GMV in the official disclosure (per company note). Segment share of Group GMV (col G) is calculated on the four regional platform segments. All figures per Delivery Hero Annual Report 2024, 'Key Figures' page.
I47: Chart data (linked)
I48: Segment | J48: GMV FY23 | K48: GMV FY24
I49: =B6 -> Europe | J49: =C7 -> 7510 | K49: =D7 -> 8878.7
I50: =B12 -> Americas | J50: =C13 -> 2451.7 | K50: =D13 -> 3642
I51: =B18 -> Asia | J51: =C19 -> 25354.2 | K51: =D19 -> 23407.4
I52: =B24 -> MENA | J52: =C25 -> 9959.3 | K52: =D25 -> 12825.9
...

Sheet Income Statement
B2: Consolidated Statement of Profit or Loss (IFRS)
B3: EUR million | FY2023 & FY2024: exact, audited (Delivery Hero Annual Report 2024) | FY2025: reported actuals (summary only)
B5: Line Item | C5: FY2023 | D5: FY2024 | E5: YoY Δ | F5: YoY % | G5: % Rev FY24
B6: Revenue | C6: 9941.9 | D6: 12294.7 | E6: =D6-C6 -> 2352.8 | F6: =IFERROR(D6/C6-1,"n/m") -> 0.23665497 | G6: 1
B7: Cost of sales | C7: -6969.2 | D7: -8965.5 | E7: =D7-C7 -> -1996.3 | F7: =IFERROR(D7/C7-1,"n/m") -> 0.28644608 | G7: =D7/D$6 -> -0.72921665
B8: Gross profit | C8: =C6+C7 -> 2972.7 | D8: =D6+D7 -> 3329.2 | E8: =D8-C8 -> 356.5 | F8: =IFERROR(D8/C8-1,"n/m") -> 0.11992465 | G8: =D8/D$6 -> 0.27078335
B9: Gross margin % (of Revenue) | C9: =C8/C6 -> 0.29900723 | D9: =D8/D6 -> 0.27078335
B10: Marketing expenses | C10: -1458.2 | D10: -1450.8 | E10: =D10-C10 -> 7.4 | F10: =IFERROR(D10/C10-1,"n/m") -> -0.0050747497 | G10: =D10/D$6 -> -0.11800207
B11: IT expenses | C11: -587.6 | D11: -531.8 | E11: =D11-C11 -> 55.8 | F11: =IFERROR(D11/C11-1,"n/m") -> -0.09496256 | G11: =D11/D$6 -> -0.04325441
B12: General & administrative expenses | C12: -1744.2 | D12: -1806.9 | E12: =D12-C12 -> -62.7 | F12: =IFERROR(D12/C12-1,"n/m") -> 0.035947712 | G12: =D12/D$6 -> -0.14696577
B13: Other operating income | C13: 76.5 | D13: 252.3 | E13: =D13-C13 -> 175.8 | F13: =IFERROR(D13/C13-1,"n/m") -> 2.2980392 | G13: =D13/D$6 -> 0.020521038
B14: Other operating expenses and goodwill impairment | C14: -885.3 | D14: -103.1 | E14: =D14-C14 -> 782.2 | F14: =IFERROR(D14/C14-1,"n/m") -> -0.8835423 | G14: =D14/D$6 -> -0.0083857272
B15: Impairment losses on trade receivables and other assets | C15: -30.9 | D15: -30.1 | E15: =D15-C15 -> 0.8 | F15: =IFERROR(D15/C15-1,"n/m") -> -0.025889968 | G15: =D15/D$6 -> -0.0024482094
B16: Operating result | C16: =C8+C10+C11+C12+C13+C14+C15 -> -1657 | D16: =D8+D10+D11+D12+D13+D14+D15 -> -341.2 | E16: =D16-C16 -> 1315.8 | F16: =IFERROR(D16/C16-1,"n/m") -> -0.7940857 | G16: =D16/D$6 -> -0.027751795
B17: Operating margin % (of Revenue) | C17: =C16/C6 -> -0.16666834 | D17: =D16/D6 -> -0.027751795
B18: Net interest result | C18: -232.2 | D18: -244.6 | E18: =D18-C18 -> -12.4 | F18: =IFERROR(D18/C18-1,"n/m") -> 0.053402239 | G18: =D18/D$6 -> -0.019894751
B19: Other financial result | C19: -266.1 | D19: 44.8 | E19: =D19-C19 -> 310.9 | F19: =IFERROR(D19/C19-1,"n/m") -> -1.1683578 | G19: =D19/D$6 -> 0.0036438465
B20: Share of profit/loss of associates and JV | C20: -7.4 | D20: -1.3 | E20: =D20-C20 -> 6.1 | F20: =IFERROR(D20/C20-1,"n/m") -> -0.82432432 | G20: =D20/D$6 -> -0.00010573662
B21: Earnings before income taxes | C21: =C16+C18+C19+C20 -> -2162.7 | D21: =D16+D18+D19+D20 -> -542.3 | E21: =D21-C21 -> 1620.4 | F21: =IFERROR(D21/C21-1,"n/m") -> -0.74924862 | G21: =D21/D$6 -> -0.044108437
B22: Income taxes | C22: -142.1 | D22: -339.3 | E22: =D22-C22 -> -197.2 | F22: =IFERROR(D22/C22-1,"n/m") -> 1.3877551 | G22: =D22/D$6 -> -0.027597257
B23: Net result | C23: =C21+C22 -> -2304.8 | D23: =D21+D22 -> -881.6 | E23: =D23-C23 -> 1423.2 | F23: =IFERROR(D23/C23-1,"n/m") -> -0.61749393 | G23: =D23/D$6 -> -0.071705694
B24: Net margin % (of Revenue) | C24: =C23/C6 -> -0.23182691 | D24: =D23/D6 -> -0.071705694
B25: Attributable to shareholders of the parent | C25: -2297.5 | D25: -882.4 | E25: =D25-C25 -> 1415.1 | F25: =IFERROR(D25/C25-1,"n/m") -> -0.61593036
B26: Attributable to non-controlling interests | C26: -7.2 | D26: 0.8 | E26: =D26-C26 -> 8 | F26: =IFERROR(D26/C26-1,"n/m") -> -1.1111111
B28: Diluted / basic EPS (EUR) | C28: -8.57 | D28: -3.1 | E28: =D28-C28 -> 5.47 | F28: =IFERROR(D28/C28-1,"n/m") -> -0.63827305
B30: Memo: EBITDA reconciliation
B31: Amortization & depreciation (per cash flow statement) | C31: 475 | D31: 465.4 | E31: =D31-C31 -> -9.6 | F31: =IFERROR(D31/C31-1,"n/m") -> -0.020210526
B32: Impairment of non-current assets (per cash flow statement) | C32: 1004.7 | D32: 133.2 | E32: =D32-C32 -> -871.5 | F32: =IFERROR(D32/C32-1,"n/m") -> -0.86742311
B33: IFRS EBITDA (Operating result + D&A + impairment) | C33: =C16+C31+C32 -> -177.3 | D33: =D16+D31+D32 -> 257.4 | E33: =D33-C33 -> 434.7 | F33: =IFERROR(D33/C33-1,"n/m") -> -2.4517766
B34: Adjusted EBITDA (company-defined, non-IFRS, per Segment Note) | C34: 253.6 | D34: 692.5 | E34: =D34-C34 -> 438.9 | F34: =IFERROR(D34/C34-1,"n/m") -> 1.7306782
B36: Note: 'Adjusted EBITDA' is Delivery Hero's non-IFRS performance measure disclosed in segment reporting; it differs from IFRS EBITDA primarily by excluding share-based payment expense, M&A and other one-off items. Source: Delivery Hero Annual Report 2024, 'Consolidated Statement of Profit or Loss', Note G, and 'Consolidated Statement of Cash Flows'.

Sheet Growth Outlook FY26E
B2: Growth Drivers & Illustrative FY2026E Outlook
B3: EUR million | Illustrative model projection — NOT company guidance. Edit blue assumption cells to flex the model.
B5: ASSUMPTIONS (editable inputs)
B6: GMV growth % FY26E (avg. of FY23–25 YoY growth) | C6: =AVERAGE('Summary & Growth'!D7:F7) -> 0.1172876
B7: Take rate FY26E (Segment Revenue / GMV) | C7: ='Summary & Growth'!G13+0.015 -> 0.30906218 | D7: Input: FY25E take rate + 1.5pp (continued AdTech/monetization gains)
B8: IFRS Revenue / Total Segment Revenue ratio | C8: 0.955 | D8: Input: ~FY23–25 historical average (95.0–96.1%)
B9: Gross margin % (of Revenue) | C9: 0.245 | D9: Input: ≈ FY25A actual (24.4%); quick-commerce/Dmart mix keeps COGS ratio above the FY24 level (27.1%)
B10: Marketing expense % of Revenue | C10: 0.09 | D10: Input: FY24 (11.8%) trended down, continuing the operating-leverage trend implied by FY25A's swing to positive Operating result
B11: IT expense % of Revenue | C11: 0.032 | D11: Input: FY24 (4.3%) trended down modestly
B12: G&A expense % of Revenue | C12: 0.11 | D12: Input: FY24 (14.7%) trended down — continued cost discipline
B13: D&A (EUR m) | C13: 460 | D13: Input: held ~flat at FY24 level (465.4)
B14: Share-based payment expense add-back (EUR m) | C14: 180 | D14: Input: FY24 actual €171.1m (per cash flow statement), held ~flat; Adjusted EBITDA (company definition) excludes this non-cash item
B15: Other net operating items % of Revenue | C15: 0.008 | D15: Input: Other op. income less other op. expense/impairment, net +€119.1m or +1.0% of Revenue in FY24; held slightly below that trend
B17: PROJECTION
B18: Metric | C18: FY2025E | D18: FY2026E
B19: GMV | C19: ='Summary & Growth'!G6 -> 52654.32 | D19: =C19*(1+$C$6) -> 58830.019
B20: Total Segment Revenue | C20: ='Summary & Growth'!G10 -> 15483.644 | D20: =D19*$C$7 -> 18182.134
B21: IFRS Revenue | C21: ='Summary & Growth'!G15 -> 14060 | D21: =D20*$C$8 -> 17363.938
B22: Revenue growth % YoY | D22: =D21/C21-1 -> 0.23498845
B23: Gross profit | C23: ='Summary & Growth'!G18 -> 3433 | D23: =D21*$C$9 -> 4254.1647
B24: Marketing expenses | D24: =-D21*$C$10 -> -1562.7544
B25: IT expenses | D25: =-D21*$C$11 -> -555.646
B26: G&A expenses | D26: =-D21*$C$12 -> -1910.0331
B27: Other net operating items | D27: =D21*$C$15 -> 138.9115
B28: Operating result (simplified) | D28: =D23+D24+D25+D26+D27 -> 364.64269
B29: Operating margin % (of Revenue) | D29: =D28/D21 -> 0.021
B30: Adjusted EBITDA proxy (Op. result + D&A + SBC) | C30: ='Summary & Growth'!G21 -> 900.25 | D30: =D28+$C$13+$C$14 -> 1004.6427
B31: Adj. EBITDA margin % (of GMV) | C31: =C30/C19 -> 0.017097363 | D31: =D30/D19 -> 0.017077042
B33: Method: FY2026E GMV grows off the FY25E base at the 3-year average GMV growth rate. Total Segment Revenue is GMV × an assumed take rate (extending the monetization trend seen in FY23–25 as AdTech and Quick Commerce mix grow). IFRS Revenue is derived from Total Segment Revenue using the historical ~95–96% conversion ratio. Gross margin is anchored to the FY25A actual (24.4%, below FY24's 27.1%, reflecting a higher mix of lower-margin Quick Commerce/Dmart sales); opex ratios are trended down from FY24 actuals to reflect continuing operating leverage, consistent with FY2025A's swing to a positive Operating result (€93.7m, the first in the company's history) after an audited FY23→FY24 improvement of +€1,315.6m (see 'Income Statement' tab). This is an illustrative, formula-driven projection for scenario testing — not a company forecast or guidance.
B39: Chart data (linked)
B40: Metric | C40: FY2025E | D40: FY2026E
B41: GMV | C41: =C19 -> 52654.32 | D41: =D19 -> 58830.019
B42: Total Segment Revenue | C42: =C20 -> 15483.644 | D42: =D20 -> 18182.134
B43: Adjusted EBITDA | C43: =C30 -> 900.25 | D43: =D30 -> 1004.6427

Sheet Sources
B2: Sources & Data Notes
B4: FY2023 & FY2024 (exact) | C4: Delivery Hero SE, Annual Report 2024 — Consolidated Statement of Profit or Loss, Consolidated Statement of Cash Flows, and 'Key Figures' segment tables (Europe, Americas, Asia, MENA, Integrated Verticals). Audited. All figures used verbatim from the filed statements.
B5: FY2021 & FY2022 (rounded) | C5: Delivery Hero SE trading updates / full-year results announcements (Q4 2021 and FY2022 press releases) for GMV and Total Segment Revenue (company-reported, rounded to nearest EUR 0.1bn); IFRS Revenue, Gross Profit, Net Result and diluted EPS from consolidated financial statements as aggregated by stockanalysis.com, cross-checked against official FY2023/FY2024 comparatives (exact match confirms consistency of methodology).
B6: FY2025 | C6: Delivery Hero SE trading update, 'Delivery Hero reaches FY 2025 targets' (published Feb 27, 2026) for Total Segment Revenue growth (+21% YoY like-for-like), GMV growth (+8% YoY like-for-like) and Adjusted EBITDA growth (+30% YoY, exceeding EUR 900m); IFRS Revenue, Gross Profit, Operating Result and Net Result from FY2025 consolidated results as aggregated by stockanalysis.com.
B7: Adj. EBITDA/GMV margins (FY21–22) | C7: Delivery Hero SE trading updates: FY2021 Adjusted EBITDA/GMV margin of -2.2%; FY2022 Group-level Adjusted EBITDA/GMV margin of -1.4% (per 'Delivery Hero concludes FY 2022' press release).
B8: Projection (FY2026E) | C8: Illustrative, formula-driven model output built on this workbook's own historical growth rates and margin trends. NOT company guidance — provided for scenario analysis; see 'Growth Outlook FY26E' tab for editable assumptions.
B10: Conventions
B11: • | C11: Blue font = hardcoded input (reported figure or model assumption). Black font = formula (calculated).
B12: • | C12: All amounts in EUR million unless stated otherwise. Fiscal year = calendar year ended December 31.
B13: • | C13: 'Total Segment Revenue' and 'GMV' are Delivery Hero's own non-IFRS operating KPIs, defined in the Annual Report as revenue before deduction of vouchers (Total Segment Revenue) and the total value of orders processed (GMV). 'Revenue' (IFRS) is the statutory income statement line.
B14: • | C14: 'Adjusted EBITDA' is Delivery Hero's company-defined non-IFRS profitability measure (segment reporting basis); it differs from 'IFRS EBITDA' (Operating result + D&A + impairment, calculated in the 'Income Statement' tab) primarily by excluding share-based payment expense and other one-off items.
