Workbook

Sheet README
A1: Delivery Hero SE — Income Statement & Growth Model
B3: Purpose
B4: A three-statement-style operating model of Delivery Hero SE (XETR: DHER), covering the consolidated IFRS income statement, group and segment growth KPIs (GMV, Total Segment Revenue, Adjusted EBITDA), and a formula-driven FY2026E–FY2028E projection built off an editable Assumptions tab.
B6: How to use this workbook
B7: • Blue text = hardcoded input (actual reported figure, or an editable forecast assumption).
B8: • Black text = formula calculated from cells on the same sheet.
B9: • Green text = formula that links to another sheet (e.g. Income Statement pulling from Assumptions).
B10: • Yellow-shaded columns = forecast years (FY2026E–FY2028E); all editable drivers live on the 'Assumptions' tab — change them there and every downstream formula recalculates.
B12: Tabs
B13: • Assumptions — editable forecast drivers (GMV growth, take rate, margins, tax rate, share count) for the 3-year projection.
B14: • Income Statement — FY2021A–FY2025A consolidated actuals plus FY2026E–FY2028E projection, from GMV down to EPS, with an Adjusted EBITDA memo and growth/margin rows throughout.
B15: • Segment & Growth — FY2023A/FY2024A segment detail (Asia, MENA, Europe, Americas, Integrated Verticals) by GMV, Segment Revenue and Adjusted EBITDA, a group KPI growth trend FY2023A–FY2028E, and supporting charts.
B17: Data provenance & known limitations
... B31: Prepared August 2026 for illustrative / analytical purposes; not investment advice.

Sheet Assumptions
A1: Delivery Hero SE — Forecast Assumptions (FY2026E-FY2028E)
A2: Blue cells are editable inputs; every downstream formula on the Income Statement and Segment & Growth tabs recalculates automatically. FY2026E GMV growth and Adjusted EBITDA margin are anchored to disclosed guidance; all else is illustrative — see README.
A4: Driver | B4: FY2025A (ref) | C4: FY2026E | D4: FY2027E | E4: FY2028E | F4: Note
A5: GMV growth % YoY | B5: ='Income Statement'!F7 -> 0.0091479673 | C5: 0.09 | D5: 0.08 | E5: 0.075 | F5: FY26 = midpoint of disclosed 8-10% YoY LfL guidance; FY27-28 illustrative moderation
A6: Segment Revenue / GMV (take rate) % | B6: ='Income Statement'!F10 -> 0.30081301 | C6: 0.305 | D6: 0.31 | E6: 0.315 | F6: Continued monetization/AdTech gains lift take rate (FY23A 23.1% -> FY24A 26.3% -> FY25A ~30.1%)
A7: Revenue (IFRS) / Total Segment Revenue % | B7: ='Income Statement'!F13 -> 0.95 | C7: 0.955 | D7: 0.955 | E7: 0.955 | F7: Held near the FY23A-FY25A average (~95.4%)
A8: Gross margin % (Gross profit / Revenue) | B8: ='Income Statement'!F18 -> 0.24416785 | C8: 0.25 | D8: 0.255 | E8: 0.26 | F8: Stabilizing after the FY23A-FY25A decline (29.9% -> 27.1% -> 24.4%) as Dmart/quick-commerce mix normalizes
A9: Adjusted EBITDA margin (% of GMV) | B9: ='Income Statement'!F46 -> 0.018353659 | C9: 0.0175 | D9: 0.02 | E9: 0.0225 | F9: FY26E calibrated within disclosed EUR 910-960m guidance; FY27-28 illustrative continued operating leverage
A10: Bridge: D&A/SBC/impairments/other (% of Segment Revenue) | B10: ='Income Statement'!F48/'Income Statement'!F8 -> 0.054682432 | C10: 0.052 | D10: 0.05 | E10: 0.048 | F10: Narrows as one-off impairments normalize (FY23A implied 18.3% of SegRev -> FY24A 8.1% -> FY25A ~5.5%)
A11: Net interest expense (% of Revenue) | B11: =-'Income Statement'!E29/'Income Statement'!E11 -> 0.019894751 | C11: 0.016 | D11: 0.014 | E11: 0.012 | F11: Gradual improvement as leverage stays low against a EUR 3.8bn cash position (FY24A ref, ~2.0% of revenue; FY25A detail not shown)
A12: Other financial result + equity-method result (EUR m) | B12: n/a | C12: 0 | D12: 0 | E12: 0 | F12: Held flat / netted to zero for simplicity — historically volatile FX and derivative-driven swing item
A13: Effective tax rate (applied only when EBT > 0) | B13: n/a | C13: 0.25 | D13: 0.25 | E13: 0.25 | F13: Normalized statutory-type rate applied prospectively once the group returns to pre-tax profit
A14: Non-controlling interests (% of Net result) | B14: n/a | C14: 0 | D14: 0 | E14: 0 | F14: Historically immaterial (<0.1% of Net result in FY23A-FY24A)
A15: Diluted share count growth % YoY | B15: n/a | C15: 0.04 | D15: 0.04 | E15: 0.04 | F15: Reflects ongoing equity-settled share-based compensation / capital increases (diluted shares grew ~5-6%/yr FY23A-FY25A)
A16: Free Cash Flow (EUR m, direct estimate) | B16: ='Income Statement'!F49 -> 200 | C16: 260 | D16: 400 | E16: 550 | F16: FY26E consistent with disclosed 'above EUR 200m' guidance; FY27-28 illustrative continued FCF ramp

Sheet Income Statement
A1: Delivery Hero SE — Consolidated Income Statement
A2: EUR million unless noted | FYE Dec 31 | FY2023A-FY2024A detail per Annual Report 2024; FY2021A/FY2022A/FY2025A summary lines only; FY2026E-FY2028E projected — see README for sources & methodology
A4: EUR million | B4: FY2021A | C4: FY2022A | D4: FY2023A | E4: FY2024A | F4: FY2025A | G4: FY2026E | H4: FY2027E | I4: FY2028E
A5: VOLUME & TOP-LINE
A6: Gross Merchandise Value (GMV) | D6: 45275.2 | E6: 48754 | F6: 49200 | G6: =F6*(1+Assumptions!C5) -> 53628 | H6: =G6*(1+Assumptions!D5) -> 57918.24 | I6: =H6*(1+Assumptions!E5) -> 62262.108
A7: % growth YoY | E7: =E6/D6-1 -> 0.076836767 | F7: =F6/E6-1 -> 0.0091479673 | G7: =G6/F6-1 -> 0.09 | H7: =H6/G6-1 -> 0.08 | I7: =I6/H6-1 -> 0.075
A8: Total Segment Revenue (non-IFRS) | D8: 10463.2 | E8: 12796.4 | F8: 14800 | G8: =G6*Assumptions!C6 -> 16356.54 | H8: =H6*Assumptions!D6 -> 17954.654 | I8: =I6*Assumptions!E6 -> 19612.564
A9: % growth YoY | E9: =E8/D8-1 -> 0.22299105 | F9: =F8/E8-1 -> 0.15657529 | G9: =G8/F8-1 -> 0.10517162 | H9: =H8/G8-1 -> 0.097704918 | I9: =I8/H8-1 -> 0.09233871
A10: Segment Revenue / GMV (take rate) % | D10: =D8/D6 -> 0.23110224 | E10: =E8/E6 -> 0.26246872 | F10: =F8/F6 -> 0.30081301 | G10: =G8/G6 -> 0.305 | H10: =H8/H6 -> 0.31 | I10: =I8/I6 -> 0.315
A11: Revenue (IFRS, consolidated) | B11: 5856 | C11: 8577 | D11: 9941.9 | E11: 12294.7 | F11: 14060 | G11: =G8*Assumptions!C7 -> 15620.496 | H11: =H8*Assumptions!D7 -> 17146.695 | I11: =I8*Assumptions!E7 -> 18729.999
A12: % growth YoY | C12: =C11/B11-1 -> 0.46465164 | D12: =D11/C11-1 -> 0.1591349 | E12: =E11/D11-1 -> 0.23665497 | F12: =F11/E11-1 -> 0.14358219 | G12: =G11/F11-1 -> 0.11098831 | H12: =H11/G11-1 -> 0.097704918 | I12: =I11/H11-1 -> 0.09233871
A13: Revenue / Total Segment Revenue % | D13: =D11/D8 -> 0.95017777 | E13: =E11/E8 -> 0.96079366 | F13: =F11/F8 -> 0.95 | G13: =G11/G8 -> 0.955 | H13: =H11/H8 -> 0.955 | I13: =I11/I8 -> 0.955
A15: PROFITABILITY
A16: Cost of sales | D16: -6969.2 | E16: -8965.5 | G16: =G17-G11 -> -11715.372 | H16: =H17-H11 -> -12774.288 | I16: =I17-I11 -> -13860.199
A17: Gross profit | B17: 1258 | C17: 2232 | D17: =D11+D16 -> 2972.7 | E17: =E11+E16 -> 3329.2 | F17: 3433 | G17: =G11*Assumptions!C8 -> 3905.1239 | H17: =H11*Assumptions!D8 -> 4372.4072 | I17: =I11*Assumptions!E8 -> 4869.7996
A18: Gross margin % | B18: =B17/B11 -> 0.2148224 | C18: =C17/C11 -> 0.26023085 | D18: =D17/D11 -> 0.29900723 | E18: =E17/E11 -> 0.27078335 | F18: =F17/F11 -> 0.24416785 | G18: =G17/G11 -> 0.25 | H18: =H17/H11 -> 0.255 | I18: =I17/I11 -> 0.26
A19: Marketing expenses | D19: -1458.2 | E19: -1450.8
A20: IT expenses | D20: -587.6 | E20: -531.8
A21: General & administrative expenses | D21: -1744.2 | E21: -1806.9
A22: Other operating income | D22: 76.5 | E22: 252.3
A23: Other operating expenses & goodwill impairment | D23: -885.3 | E23: -103.1
A24: Impairment losses on trade receivables & other assets | D24: -30.9 | E24: -30.1
A25: Operating result (EBIT) | B25: -1659 | C25: -1437 | D25: =D17+D19+D20+D21+D22+D23+D24 -> -1657 | E25: =E17+E19+E20+E21+E22+E23+E24 -> -341.2 | F25: 93.7 | G25: =G44-G48 -> 87.94992 | H25: =H44-H48 -> 260.63208 | I25: =I44-I48 -> 459.49436
A26: Operating margin % | B26: =B25/B11 -> -0.28329918 | C26: =C25/C11 -> -0.1675411 | D26: =D25/D11 -> -0.16666834 | E26: =E25/E11 -> -0.027751795 | F26: =F25/F11 -> 0.0066642959 | G26: =G25/G11 -> 0.005630418 | H26: =H25/H11 -> 0.015200135 | I26: =I25/I11 -> 0.024532536
A28: BELOW EBIT
A29: Net interest result | D29: -232.2 | E29: -244.6 | G29: =-G11*Assumptions!C11 -> -249.92793 | H29: =-H11*Assumptions!D11 -> -240.05373 | I29: =-I11*Assumptions!E11 -> -224.75998
A30: Other financial result | D30: -266.1 | E30: 44.8 | G30: =Assumptions!C12 -> 0 | H30: =Assumptions!D12 -> 0 | I30: =Assumptions!E12 -> 0
A31: Share of profit/loss of equity-method investees | D31: -7.4 | E31: -1.3 | G31: 0 | H31: 0 | I31: 0
A32: Earnings before income taxes (EBT) | D32: =D25+D29+D30+D31 -> -2162.7 | E32: =E25+E29+E30+E31 -> -542.3 | G32: =G25+G29+G30+G31 -> -161.97801 | H32: =H25+H29+H30+H31 -> 20.578351 | I32: =I25+I29+I30+I31 -> 234.73437
A33: Income taxes | D33: -142.1 | E33: -339.3 | G33: =IF(G32>0,-G32*Assumptions!C13,0) -> 0 | H33: =IF(H32>0,-H32*Assumptions!D13,0) -> -5.1445877 | I33: =IF(I32>0,-I32*Assumptions!E13,0) -> -58.683593
A34: Net result | D34: =D32+D33 -> -2304.8 | E34: =E32+E33 -> -881.6 | G34: =G32+G33 -> -161.97801 | H34: =H32+H33 -> 15.433763 | I34: =I32+I33 -> 176.05078
A35: Non-controlling interests | D35: -7.2 | E35: 0.8 | G35: =G34*Assumptions!C14 -> 0 | H35: =H34*Assumptions!D14 -> 0 | I35: =I34*Assumptions!E14 -> 0
A36: Net result attributable to shareholders of the parent | B36: -1124 | C36: -3008 | D36: =D34-D35 -> -2297.6 | E36: =E34-E35 -> -882.4 | F36: -782.9 | G36: =G34-G35 -> -161.97801 | H36: =H34-H35 -> 15.433763 | I36: =I34-I35 -> 176.05078
A37: Net margin % | B37: =B36/B11 -> -0.19193989 | C37: =C36/C11 -> -0.35070537 | D37: =D36/D11 -> -0.23110271 | E37: =E36/E11 -> -0.071770763 | F37: =F36/F11 -> -0.055682788 | G37: =G36/G11 -> -0.010369582 | H37: =H36/H11 -> 0.00090010133 | I37: =I36/I11 -> 0.0093994016
A39: PER SHARE
A40: Diluted & basic EPS (EUR) | B40: -4.57 | C40: -11.28 | D40: -8.57 | E40: -3.1 | F40: -2.62 | G40: =G36/G41 -> -0.52121598 | H40: =H36/H41 -> 0.047752943 | I40: =I36/I41 -> 0.52376073
A41: Diluted shares outstanding (million) | B41: =B36/B40 -> 245.95186 | C41: =C36/C40 -> 266.66667 | D41: =D36/D40 -> 268.09802 | E41: =E36/E40 -> 284.64516 | F41: =F36/F40 -> 298.81679 | G41: =F41*(1+Assumptions!C15) -> 310.76947 | H41: =G41*(1+Assumptions!D15) -> 323.20024 | I41: =H41*(1+Assumptions!E15) -> 336.12825
A43: MEMO: ADJUSTED EBITDA (non-IFRS)
A44: Adjusted EBITDA | D44: 253.6 | E44: 692.5 | F44: 903 | G44: =G6*Assumptions!C9 -> 938.49 | H44: =H6*Assumptions!D9 -> 1158.3648 | I44: =I6*Assumptions!E9 -> 1400.8974
A45: % growth YoY | E45: =E44/D44-1 -> 1.7306782 | F45: =F44/E44-1 -> 0.30397112 | G45: =G44/F44-1 -> 0.039302326 | H45: =H44/G44-1 -> 0.23428571 | I45: =I44/H44-1 -> 0.209375
...

Sheet Segment & Growth
A1: Delivery Hero SE — Segment & Growth Detail
A2: EUR million unless noted | Segment table per Annual Report 2024 (Key Figures, p.4); KPI trend links to Income Statement tab
A4: SEGMENT DETAIL — FY2024A vs FY2023A (as reported)
A5: Segment | B5: GMV FY24A | C5: GMV FY23A | D5: GMV grow% | E5: Seg.Rev FY24A | F5: Seg.Rev FY23A | G5: Seg.Rev grow% | H5: Adj.EBITDA FY24A | I5: Adj.EBITDA FY23A | J5: Adj.EBITDA grow% | K5: Adj.EBITDA/GMV FY24A | L5: Adj.EBITDA/GMV FY23A
A6: Asia | B6: 23407.4 | C6: 25354.2 | D6: =B6/C6-1 -> -0.076784123 | E6: 4071.9 | F6: 3729.4 | G6: =E6/F6-1 -> 0.091837829 | H6: 385.1 | I6: 385 | J6: =H6/I6-1 -> 0.00025974026 | K6: =H6/B6 -> 0.016452062 | L6: =I6/C6 -> 0.015184861
A7: MENA | B7: 12825.9 | C7: 9959.3 | D7: =B7/C7-1 -> 0.28783147 | E7: 3527.8 | F7: 2700.8 | G7: =E7/F7-1 -> 0.30620557 | H7: 472.9 | I7: 304.6 | J7: =H7/I7-1 -> 0.55252791 | K7: =H7/B7 -> 0.036870707 | L7: =I7/C7 -> 0.030584479
A8: Europe | B8: 8878.7 | C8: 7510 | D8: =B8/C8-1 -> 0.18225033 | E8: 1891.9 | F8: 1522.4 | G8: =E8/F8-1 -> 0.24270888 | H8: -77 | I8: -168.2 | J8: =H8/I8-1 -> -0.54221165 | K8: =H8/B8 -> -0.0086724408 | L8: =I8/C8 -> -0.022396804
A9: Americas | B9: 3642 | C9: 2451.7 | D9: =B9/C9-1 -> 0.48549986 | E9: 939.6 | F9: 651 | G9: =E9/F9-1 -> 0.44331797 | H9: 10.3 | I9: -49.9 | J9: =H9/I9-1 -> -1.2064128 | K9: =H9/B9 -> 0.0028281164 | L9: =I9/C9 -> -0.020353224
A10: Integrated Verticals | B10: 2904.7 | C10: 2224.4 | D10: =B10/C10-1 -> 0.30583528 | E10: 2709.8 | F10: 2126.1 | G10: =E10/F10-1 -> 0.27454024 | H10: -98.7 | I10: -217.9 | J10: =H10/I10-1 -> -0.54703993 | K10: =H10/B10 -> -0.033979413 | L10: =I10/C10 -> -0.097959
A11: Group Total | B11: 48754 | C11: 45275.2 | D11: =B11/C11-1 -> 0.076836767 | E11: 12796.4 | F11: 10463.2 | G11: =E11/F11-1 -> 0.22299105 | H11: 692.5 | I11: 253.6 | J11: =H11/I11-1 -> 1.7306782 | K11: =H11/B11 -> 0.014203963 | L11: =I11/C11 -> 0.0056013005
A13: Note: Group Total is reported directly (not a sum of segments) because Total Segment Revenue and GMV include intersegment consolidation adjustments; Integrated Verticals GMV is shown for illustrative purposes only and is also captured within the platform segments.
A15: GROUP KPI GROWTH TREND — FY2023A-FY2028E
A16: EUR million | B16: FY2023A | C16: FY2024A | D16: FY2025A | E16: FY2026E | F16: FY2027E | G16: FY2028E
A17: Gross Merchandise Value (GMV) | B17: ='Income Statement'!D6 -> 45275.2 | C17: ='Income Statement'!E6 -> 48754 | D17: ='Income Statement'!F6 -> 49200 | E17: ='Income Statement'!G6 -> 53628 | F17: ='Income Statement'!H6 -> 57918.24 | G17: ='Income Statement'!I6 -> 62262.108
A18: % growth YoY | C18: =C17/B17-1 -> 0.076836767 | D18: =D17/C17-1 -> 0.0091479673 | E18: =E17/D17-1 -> 0.09 | F18: =F17/E17-1 -> 0.08 | G18: =G17/F17-1 -> 0.075
A19: Total Segment Revenue | B19: ='Income Statement'!D8 -> 10463.2 | C19: ='Income Statement'!E8 -> 12796.4 | D19: ='Income Statement'!F8 -> 14800 | E19: ='Income Statement'!G8 -> 16356.54 | F19: ='Income Statement'!H8 -> 17954.654 | G19: ='Income Statement'!I8 -> 19612.564
A20: % growth YoY | C20: =C19/B19-1 -> 0.22299105 | D20: =D19/C19-1 -> 0.15657529 | E20: =E19/D19-1 -> 0.10517162 | F20: =F19/E19-1 -> 0.097704918 | G20: =G19/F19-1 -> 0.09233871
A21: Revenue (IFRS) | B21: ='Income Statement'!D11 -> 9941.9 | C21: ='Income Statement'!E11 -> 12294.7 | D21: ='Income Statement'!F11 -> 14060 | E21: ='Income Statement'!G11 -> 15620.496 | F21: ='Income Statement'!H11 -> 17146.695 | G21: ='Income Statement'!I11 -> 18729.999
A22: % growth YoY | C22: =C21/B21-1 -> 0.23665497 | D22: =D21/C21-1 -> 0.14358219 | E22: =E21/D21-1 -> 0.11098831 | F22: =F21/E21-1 -> 0.097704918 | G22: =G21/F21-1 -> 0.09233871
A23: Gross profit | B23: ='Income Statement'!D17 -> 2972.7 | C23: ='Income Statement'!E17 -> 3329.2 | D23: ='Income Statement'!F17 -> 3433 | E23: ='Income Statement'!G17 -> 3905.1239 | F23: ='Income Statement'!H17 -> 4372.4072 | G23: ='Income Statement'!I17 -> 4869.7996
A24: Gross margin % | B24: =B23/B21 -> 0.29900723 | C24: =C23/C21 -> 0.27078335 | D24: =D23/D21 -> 0.24416785 | E24: =E23/E21 -> 0.25 | F24: =F23/F21 -> 0.255 | G24: =G23/G21 -> 0.26
A25: Adjusted EBITDA | B25: ='Income Statement'!D44 -> 253.6 | C25: ='Income Statement'!E44 -> 692.5 | D25: ='Income Statement'!F44 -> 903 | E25: ='Income Statement'!G44 -> 938.49 | F25: ='Income Statement'!H44 -> 1158.3648 | G25: ='Income Statement'!I44 -> 1400.8974
A26: % growth YoY | C26: =C25/B25-1 -> 1.7306782 | D26: =D25/C25-1 -> 0.30397112 | E26: =E25/D25-1 -> 0.039302326 | F26: =F25/E25-1 -> 0.23428571 | G26: =G25/F25-1 -> 0.209375
A27: Adjusted EBITDA margin (% of GMV) | B27: =B25/B17 -> 0.0056013005 | C27: =C25/C17 -> 0.014203963 | D27: =D25/D17 -> 0.018353659 | E27: =E25/E17 -> 0.0175 | F27: =F25/F17 -> 0.02 | G27: =G25/G17 -> 0.0225
A28: Operating result (EBIT) | B28: ='Income Statement'!D25 -> -1657 | C28: ='Income Statement'!E25 -> -341.2 | D28: ='Income Statement'!F25 -> 93.7 | E28: ='Income Statement'!G25 -> 87.94992 | F28: ='Income Statement'!H25 -> 260.63208 | G28: ='Income Statement'!I25 -> 459.49436
A29: Net result attributable to parent | B29: ='Income Statement'!D36 -> -2297.6 | C29: ='Income Statement'!E36 -> -882.4 | D29: ='Income Statement'!F36 -> -782.9 | E29: ='Income Statement'!G36 -> -161.97801 | F29: ='Income Statement'!H36 -> 15.433763 | G29: ='Income Statement'!I36 -> 176.05078
A30: Free Cash Flow (memo) | B30: ='Income Statement'!D49 -> -366 | C30: ='Income Statement'!E49 -> 100 | D30: ='Income Statement'!F49 -> 200 | E30: ='Income Statement'!G49 -> 260 | F30: ='Income Statement'!H49 -> 400 | G30: ='Income Statement'!I49 -> 550
A31: SEGMENT MIX — FY2024A
A32: Segment | B32: GMV FY24A | C32: Segment Revenue FY24A | D32: Adj. EBITDA FY24A
A33: =A6 -> Asia | B33: =B6 -> 23407.4 | C33: =E6 -> 4071.9 | D33: =H6 -> 385.1
A34: =A7 -> MENA | B34: =B7 -> 12825.9 | C34: =E7 -> 3527.8 | D34: =H7 -> 472.9
A35: =A8 -> Europe | B35: =B8 -> 8878.7 | C35: =E8 -> 1891.9 | D35: =H8 -> -77
A36: =A9 -> Americas | B36: =B9 -> 3642 | C36: =E9 -> 939.6 | D36: =H9 -> 10.3
A37: =A10 -> Integrated Verticals | B37: =B10 -> 2904.7 | C37: =E10 -> 2709.8 | D37: =H10 -> -98.7
A39: Note: FY2025A GMV/Segment Revenue growth in the table above is as-reported (EUR); Delivery Hero's own disclosed FY2025 headline growth was like-for-like / constant-currency (+9.0% GMV, +23.1% Total Segment Revenue) and was materially higher due to FX/hyperinflation translation headwinds (notably Turkey and Argentina). See Income Statement tab notes for detail.
