Workbook

Sheet Cover
B2: Delivery Hero SE — Income Statement Model
B5: Consolidated Income Statement, FY2021A–FY2025A (audited) with a FY2026E guidance-based plan; segment growth detail included.
B6: All figures in EUR million unless noted. Fiscal year = calendar year. Model prepared 2026-08-17.
B8: Contents
B9: ▸ Income Statement — Full consolidated P&L, FY2021A–FY2025A actuals + FY2026E plan, with margin and YoY growth detail.
B10: ▸ Assumptions — Editable FY2026E plan drivers (revenue growth, cost ratios) benchmarked to FY2025A and company guidance.
B11: ▸ Growth & Segments — GMV, Total Segment Revenue and Adjusted EBITDA by region (Asia, MENA, Europe, Americas, Integrated Verticals): growth rates, CAGR, revenue mix, FY2026E guidance.
B12: ▸ Sources & Notes — Citations for every figure, and portfolio/comparability notes (Glovo, Talabat, Foodpanda Asia, pending Uber acquisition).
B14: Key context affecting comparability
B15: • Glovo (Spain-based platform, active in ~20 countries): Delivery Hero became majority shareholder (~94%) on July 4, 2022, and has fully consolidated it since; FY2022 therefore includes only ~6 months of Glovo vs. 12 months from FY2023 onward.
B16: • Woowa Brothers / Baemin (South Korea): 88.5% stake closed March 4, 2021, consolidated into the Asia segment from that date. As a condition of Korean antitrust approval, the pre-existing Delivery Hero Korea / Yogiyo business (€536.0m disposal) was divested on October 29, 2021 and excluded from Asia segment KPIs from January 2021.
B17: • Talabat (MENA): ~20% free float IPO'd on the Dubai Financial Market on December 10, 2024 (~$2.0bn gross proceeds). Delivery Hero retained ~80% and continues to fully consolidate Talabat within the MENA segment (the public float is recognized as a non-controlling interest).
... B22: Color key: blue = hardcoded input / reported actual or company guidance | black = formula | yellow fill = FY2026E plan / assumption

Sheet Income Statement
A1: Delivery Hero SE — Consolidated Income Statement (EUR million)
A2: IFRS consolidated P&L. Blue = reported actual; black = formula; yellow column = FY2026E plan (see Assumptions tab).
A4: EUR million | B4: Note | C4: FY2021A | D4: FY2022A | E4: FY2023A | F4: FY2024A | G4: FY2025A | H4: FY2026E
A6: Revenue | B6: AR21 p.108; AR23 p.90; AR25 p.166 | C6: 5855.6 | D6: 8577.3 | E6: 9941.9 | F6: 12294.7 | G6: 14059.6 | H6: =G6*(1+Assumptions!B5) -> 16168.54
A7: Cost of sales | B7: Note G.2, AR25 p.166 | C7: -4597.6 | D7: -6345.5 | E7: -6969.2 | F7: -8965.5 | G7: -10626.5 | H7: =-H6*Assumptions!B9 -> -12223.416
A8: Gross profit | C8: =C6+C7 -> 1258 | D8: =D6+D7 -> 2231.8 | E8: =E6+E7 -> 2972.7 | F8: =F6+F7 -> 3329.2 | G8: =G6+G7 -> 3433.1 | H8: =H6+H7 -> 3945.1238
A9: Gross margin % | C9: =C8/C6 -> 0.21483708 | D9: =D8/D6 -> 0.26019843 | E9: =E8/E6 -> 0.29900723 | F9: =F8/F6 -> 0.27078335 | G9: =G8/G6 -> 0.24418191 | H9: =H8/H6 -> 0.244
A11: Marketing expenses | B11: Note G.3 | C11: -1300.3 | D11: -1465.6 | E11: -1458.2 | F11: -1450.8 | G11: -1419.6 | H11: =-H6*Assumptions!B10 -> -1633.0225
A12: IT expenses | B12: Note G.4 | C12: -310.9 | D12: -517.3 | E12: -587.6 | F12: -531.8 | G12: -485 | H12: =-H6*Assumptions!B11 -> -549.73036
A13: General & administrative expenses | B13: Note G.5 | C13: -1317.5 | D13: -1724.6 | E13: -1744.2 | F13: -1806.9 | G13: -1411.3 | H13: =-H6*Assumptions!B12 -> -1616.854
A14: Other operating income | B14: Note G.6 | C14: 732.1 | D14: 45.9 | E14: 76.5 | F14: 252.3 | G14: 38.8 | H14: =H6*Assumptions!B13 -> 48.50562
A15: Other operating expenses & goodwill impairment | B15: Note G.7 | C15: -105.6 | D15: -825.9 | E15: -885.3 | F15: -103.1 | G15: -274.1 | H15: =-H6*Assumptions!B14 -> -323.3708
A16: Impairment losses, trade receivables & other assets | B16: AR25 p.166 | C16: -35.4 | D16: -38.9 | E16: -30.9 | F16: -30.1 | G16: -35.9 | H16: =-H6*Assumptions!B15 -> -48.50562
A17: Operating result (EBIT) | C17: =C8+C11+C12+C13+C14+C15+C16 -> -1079.6 | D17: =D8+D11+D12+D13+D14+D15+D16 -> -2294.6 | E17: =E8+E11+E12+E13+E14+E15+E16 -> -1657 | F17: =F8+F11+F12+F13+F14+F15+F16 -> -341.2 | G17: =G8+G11+G12+G13+G14+G15+G16 -> -154 | H17: =H8+H11+H12+H13+H14+H15+H16 -> -177.85394
A18: EBIT margin % | C18: =C17/C6 -> -0.18437052 | D18: =D17/D6 -> -0.26752008 | E18: =E17/E6 -> -0.16666834 | F18: =F17/F6 -> -0.027751795 | G18: =G17/G6 -> -0.01095337 | H18: =H17/H6 -> -0.011
A20: Net interest result | B20: Note G.8 | C20: -120.1 | D20: -179.1 | E20: -232.2 | F20: -244.6 | G20: -283.1 | H20: =-H6*Assumptions!B16 -> -323.3708
A21: Other financial result | B21: Note G.9 | C21: 420.6 | D21: -257.2 | E21: -266.1 | F21: 44.8 | G21: -28.8 | H21: =Assumptions!B19 -> -83.4
A22: Share of profit/(loss), associates & JVs (equity method) | B22: Note D.3.b | C22: -179.4 | D22: -121.4 | E22: -7.4 | F22: -1.3 | G22: -1.5 | H22: =Assumptions!B20 -> -1.5
A23: Earnings before income taxes (EBT) | C23: =C17+C20+C21+C22 -> -958.5 | D23: =D17+D20+D21+D22 -> -2852.3 | E23: =E17+E20+E21+E22 -> -2162.7 | F23: =F17+F20+F21+F22 -> -542.3 | G23: =G17+G20+G21+G22 -> -467.4 | H23: =H17+H20+H21+H22 -> -586.12474
A24: Income taxes | B24: Note G.10 | C24: -138.2 | D24: -141.2 | E24: -142.1 | F24: -339.3 | G24: -230.7 | H24: =Assumptions!B21 -> -230.7
A25: Net result (consolidated) | C25: =C23+C24 -> -1096.7 | D25: =D23+D24 -> -2993.5 | E25: =E23+E24 -> -2304.8 | F25: =F23+F24 -> -881.6 | G25: =G23+G24 -> -698.1 | H25: =H23+H24 -> -816.82474
A26: Net margin % | C26: =C25/C6 -> -0.1872908 | D26: =D25/D6 -> -0.3490026 | E26: =E25/E6 -> -0.23182691 | F26: =F25/F6 -> -0.071705694 | G26: =G25/G6 -> -0.049652906 | H26: =H25/H6 -> -0.050519388
A28: Non-controlling interests | B28: FY21 n.d.* | C28: 0 | D28: 14.9 | E28: -7.2 | F28: 0.8 | G28: 84.6 | H28: =Assumptions!B22 -> 84.6
A29: Attributable to shareholders of the parent | C29: =C25-C28 -> -1096.7 | D29: =D25-D28 -> -3008.4 | E29: =E25-E28 -> -2297.6 | F29: =F25-F28 -> -882.4 | G29: =G25-G28 -> -782.7 | H29: =H25-H28 -> -901.42474
A30: Diluted / basic EPS (EUR) | B30: Reported | C30: -4.47 | D30: -11.28 | E30: -8.57 | F30: -3.1 | G30: -2.62 | H30: =H29/H31 -> -3.0174177
A31: Implied weighted-avg. diluted shares (million) | C31: =C29/C30 -> 245.34676 | D31: =D29/D30 -> 266.70213 | E31: =E29/E30 -> 268.09802 | F31: =F29/F30 -> 284.64516 | G31: =G29/G30 -> 298.74046 | H31: =Assumptions!B23 -> 298.74046
A33: Memo: non-GAAP & KPIs
A34: Adjusted EBITDA (non-GAAP, Group) | B34: Key Figures p.4/120 | C34: -795.6 | D34: -467.2 | E34: 253.6 | F34: 692.5 | G34: 903 | H34: =Assumptions!B28 -> 935
A35: Group GMV | B35: Key Figures p.4/120 | C35: 32518.9 | D35: 42826.8 | E35: 45275.2 | F35: 48754 | G35: 49196.8 | H35: =G35*(1+Assumptions!B6) -> 53624.512
A36: Adjusted EBITDA margin, % of GMV | C36: =C34/C35 -> -0.024465772 | D36: =D34/D35 -> -0.010909057 | E36: =E34/E35 -> 0.0056013005 | F36: =F34/F35 -> 0.014203963 | G36: =G34/G35 -> 0.018354852 | H36: =H34/H35 -> 0.017436056
A37: Total Segment Revenue | B37: Key Figures p.4/120 | C37: 6389.8 | D37: 9218.9 | E37: 10463.2 | F37: 12796.4 | G37: 14803.4 | H37: =G37*(1+Assumptions!B5) -> 17023.91
A39: Memo: YoY growth (blank = no prior-year base in this model)
A40: Revenue growth % | D40: =(D6-C6)/ABS(C6) -> 0.46480292 | E40: =(E6-D6)/ABS(D6) -> 0.15909435 | F40: =(F6-E6)/ABS(E6) -> 0.23665497 | G40: =(G6-F6)/ABS(F6) -> 0.14354966 | H40: =(H6-G6)/ABS(G6) -> 0.15
A41: Gross profit growth % | D41: =(D8-C8)/ABS(C8) -> 0.77408585 | E41: =(E8-D8)/ABS(D8) -> 0.33197419 | F41: =(F8-E8)/ABS(E8) -> 0.11992465 | G41: =(G8-F8)/ABS(F8) -> 0.031208699 | H41: =(H8-G8)/ABS(G8) -> 0.14914327
A42: Total Segment Revenue growth % | D42: =(D37-C37)/ABS(C37) -> 0.44275251 | E42: =(E37-D37)/ABS(D37) -> 0.13497272 | F42: =(F37-E37)/ABS(E37) -> 0.22299105 | G42: =(G37-F37)/ABS(F37) -> 0.15684099 | H42: =(H37-G37)/ABS(G37) -> 0.15
A43: GMV growth % | D43: =(D35-C35)/ABS(C35) -> 0.31698182 | E43: =(E35-D35)/ABS(D35) -> 0.05716981 | F43: =(F35-E35)/ABS(E35) -> 0.076836767 | G43: =(G35-F35)/ABS(F35) -> 0.0090823317 | H43: =(H35-G35)/ABS(G35) -> 0.09
A44: Adjusted EBITDA growth % (vs. |prior|, turnaround metric) | D44: =(D34-C34)/ABS(C34) -> 0.41277024 | E44: =(E34-D34)/ABS(D34) -> 1.5428082 | F44: =(F34-E34)/ABS(E34) -> 1.7306782 | G44: =(G34-F34)/ABS(F34) -> 0.30397112 | H44: =(H34-G34)/ABS(G34) -> 0.035437431
A45: EBIT, absolute Δ (EUR m) | D45: =D17-C17 -> -1215 | E45: =E17-D17 -> 637.6 | F45: =F17-E17 -> 1315.8 | G45: =G17-F17 -> 187.2 | H45: =H17-G17 -> -23.85394
A46: Net result, absolute Δ (EUR m) | D46: =D25-C25 -> -1896.8 | E46: =E25-D25 -> 688.7 | F46: =F25-E25 -> 1423.2 | G46: =G25-F25 -> 183.5 | H46: =H25-G25 -> -118.72474
A48: Memo: FY2025A reported vs. like-for-like / constant-currency growth (company-reported, FX distortion flagged)
...

Sheet Assumptions
A1: FY2026E Plan — Assumptions
A2: Editable drivers (blue, yellow fill) that feed the FY2026E column on the Income Statement tab. Defaults = FY2025A actual ratios except where company guidance is used.
A4: Driver | B4: FY2026E assumption | C4: FY2025A reference | D4: Basis
A5: Revenue growth, FY2026E (applied to IFRS Revenue) | B5: 0.15 | D5: Company guidance: Total Segment Revenue +14% to +16% (LFL/CC) for FY2026; midpoint used as proxy for IFRS revenue growth.
A6: GMV growth, FY2026E | B6: 0.09 | D6: Company guidance: GMV +8% to +10% for FY2026; midpoint used.
A8: Cost ratios (% of Revenue) — defaulted to FY2025A actual
A9: Cost of sales, % of revenue | B9: 0.756 | C9: =-'Income Statement'!G7/'Income Statement'!G6 -> 0.75581809 | D9: FY2025A: 10,626.5 / 14,059.6 = 75.6%.
A10: Marketing expenses, % of revenue | B10: 0.101 | C10: =-'Income Statement'!G11/'Income Statement'!G6 -> 0.10097016 | D10: FY2025A: 1,419.6 / 14,059.6 = 10.1%.
A11: IT expenses, % of revenue | B11: 0.034 | C11: =-'Income Statement'!G12/'Income Statement'!G6 -> 0.034496003 | D11: FY2025A: 485.0 / 14,059.6 = 3.4%.
A12: General & administrative expenses, % of revenue | B12: 0.1 | C12: =-'Income Statement'!G13/'Income Statement'!G6 -> 0.10037981 | D12: FY2025A: 1,411.3 / 14,059.6 = 10.0%.
A13: Other operating income, % of revenue | B13: 0.003 | C13: ='Income Statement'!G14/'Income Statement'!G6 -> 0.0027596802 | D13: FY2025A: 38.8 / 14,059.6 = 0.3%. Volatile, non-recurring-heavy line.
A14: Other operating expenses & goodwill impairment, % of revenue | B14: 0.02 | C14: =-'Income Statement'!G15/'Income Statement'!G6 -> 0.019495576 | D14: FY2025A: 274.1 / 14,059.6 = 2.0%. Includes legal/antitrust provisions historically — volatile.
A15: Impairment losses, trade receivables & other assets, % of revenue | B15: 0.003 | C15: =-'Income Statement'!G16/'Income Statement'!G6 -> 0.0025534155 | D15: FY2025A: 35.9 / 14,059.6 = 0.3%.
A16: Net interest result, % of revenue | B16: 0.02 | C16: =-'Income Statement'!G20/'Income Statement'!G6 -> 0.020135708 | D16: FY2025A: 283.1 / 14,059.6 = 2.0%. Risk: Feb 2026 $1.4bn term loan (bond refinancing) could raise FY2026 interest expense above this ratio.
A18: Other P&L lines (EUR million, held flat at FY2025A)
A19: Other financial result, EUR m | B19: -83.4 | C19: =AVERAGE('Income Statement'!E21:G21) -> -83.366667 | D19: FX-driven, volatile (FY23: -266.1; FY24: +44.8; FY25: -28.8). Held at 3-yr average rather than FY2025A alone.
A20: Share of profit/(loss), associates & JVs, EUR m | B20: -1.5 | C20: ='Income Statement'!G22 -> -1.5 | D20: Held flat at FY2025A; line is now immaterial post-Glovo full consolidation.
A21: Income taxes, EUR m | B21: -230.7 | C21: ='Income Statement'!G24 -> -230.7 | D21: Held flat at FY2025A EUR level (effective-rate approach unreliable near EBT breakeven with NOL carryforwards).
A22: Non-controlling interests, EUR m | B22: 84.6 | C22: ='Income Statement'!G28 -> 84.6 | D22: Held flat at FY2025A; reflects Talabat's ~20% public free float continuing to earn a profit share in MENA.
A23: Implied weighted-avg. diluted shares, million | B23: ='Income Statement'!G31 -> 298.74046 | C23: ='Income Statement'!G31 -> 298.74046 | D23: Held flat at FY2025A implied share count (formula, see B-column).
A25: Company guidance, FY2026E (reference only — not a bottom-up derivation)
A26: Adjusted EBITDA guidance, low (EUR m) | B26: 910 | D26: Confirmed at FY2025 results (Feb/Mar 2026); confidence raised to upper half of range at Q1 2026 trading update.
A27: Adjusted EBITDA guidance, high (EUR m) | B27: 960
A28: Adjusted EBITDA guidance, midpoint (EUR m) | B28: =AVERAGE(B26:B27) -> 935 | D28: Used as the Adjusted EBITDA memo figure for FY2026E on the Income Statement tab. Not derived from the modeled IFRS EBIT bridge (D&A, SBC and legal/restructuring add-backs are not modeled at this line-item level).
A29: Free Cash Flow guidance (EUR m, floor) | B29: 200 | D29: Guided '>€200m'; excludes extraordinary cash outflows for antitrust/rider-related legal matters.

Sheet Growth & Segments
A1: Delivery Hero SE — Growth & Segment Detail (EUR million except %)
A2: GMV, Total Segment Revenue and Adjusted EBITDA by region. Group KPIs link to the Income Statement tab; segment figures are reported inputs (blue).
A4: EUR million | C4: FY2021A | D4: FY2022A | E4: FY2023A | F4: FY2024A | G4: FY2025A | H4: FY2026E | I4: CAGR '21–'25
A6: Group KPIs
A7: Group GMV | C7: ='Income Statement'!C35 -> 32518.9 | D7: ='Income Statement'!D35 -> 42826.8 | E7: ='Income Statement'!E35 -> 45275.2 | F7: ='Income Statement'!F35 -> 48754 | G7: ='Income Statement'!G35 -> 49196.8 | H7: ='Income Statement'!H35 -> 53624.512 | I7: =IFERROR((G7/C7)^(1/4)-1,"n/m") -> 0.10904777
A8: YoY growth % | D8: =(D7-C7)/ABS(C7) -> 0.31698182 | E8: =(E7-D7)/ABS(D7) -> 0.05716981 | F8: =(F7-E7)/ABS(E7) -> 0.076836767 | G8: =(G7-F7)/ABS(F7) -> 0.0090823317 | H8: =(H7-G7)/ABS(G7) -> 0.09
A10: Total Segment Revenue | C10: ='Income Statement'!C37 -> 6389.8 | D10: ='Income Statement'!D37 -> 9218.9 | E10: ='Income Statement'!E37 -> 10463.2 | F10: ='Income Statement'!F37 -> 12796.4 | G10: ='Income Statement'!G37 -> 14803.4 | H10: ='Income Statement'!H37 -> 17023.91 | I10: =IFERROR((G10/C10)^(1/4)-1,"n/m") -> 0.23372553
A11: YoY growth % | D11: =(D10-C10)/ABS(C10) -> 0.44275251 | E11: =(E10-D10)/ABS(D10) -> 0.13497272 | F11: =(F10-E10)/ABS(E10) -> 0.22299105 | G11: =(G10-F10)/ABS(F10) -> 0.15684099 | H11: =(H10-G10)/ABS(G10) -> 0.15
A13: Revenue (IFRS) | C13: ='Income Statement'!C6 -> 5855.6 | D13: ='Income Statement'!D6 -> 8577.3 | E13: ='Income Statement'!E6 -> 9941.9 | F13: ='Income Statement'!F6 -> 12294.7 | G13: ='Income Statement'!G6 -> 14059.6 | H13: ='Income Statement'!H6 -> 16168.54 | I13: =IFERROR((G13/C13)^(1/4)-1,"n/m") -> 0.24480232
A14: YoY growth % | D14: =(D13-C13)/ABS(C13) -> 0.46480292 | E14: =(E13-D13)/ABS(D13) -> 0.15909435 | F14: =(F13-E13)/ABS(E13) -> 0.23665497 | G14: =(G13-F13)/ABS(F13) -> 0.14354966 | H14: =(H13-G13)/ABS(G13) -> 0.15
A16: Adjusted EBITDA (non-GAAP) | C16: ='Income Statement'!C34 -> -795.6 | D16: ='Income Statement'!D34 -> -467.2 | E16: ='Income Statement'!E34 -> 253.6 | F16: ='Income Statement'!F34 -> 692.5 | G16: ='Income Statement'!G34 -> 903 | H16: ='Income Statement'!H34 -> 935 | I16: n/m (sign change)
A17: YoY growth % (vs. |prior|) | D17: =(D16-C16)/ABS(C16) -> 0.41277024 | E17: =(E16-D16)/ABS(D16) -> 1.5428082 | F17: =(F16-E16)/ABS(E16) -> 1.7306782 | G17: =(G16-F16)/ABS(F16) -> 0.30397112 | H17: =(H16-G16)/ABS(G16) -> 0.035437431
A20: Segment: Asia
A21: Segment Revenue | B21: Key Figures p.4-5/120-121 | C21: 2897.3 | D21: 3803.6 | E21: 3729.4 | F21: 4071.9 | G21: 4417.7 | I21: =IFERROR((G21/C21)^(1/4)-1,"n/m") -> 0.11122164
A22: YoY growth % | D22: =(D21-C21)/ABS(C21) -> 0.31280848 | E22: =(E21-D21)/ABS(D21) -> -0.019507835 | F22: =(F21-E21)/ABS(E21) -> 0.091837829 | G22: =(G21-F21)/ABS(F21) -> 0.0849235
A23: Revenue mix, % of Total Segment Revenue | C23: =C21/C10 -> 0.45342577 | D23: =D21/D10 -> 0.41258719 | E23: =E21/E10 -> 0.35643016 | F23: =F21/F10 -> 0.31820668 | G23: =G21/G10 -> 0.29842469
A24: Segment GMV | B24: Key Figures p.4-5/120-121 | C24: 21064.5 | D24: 26910.4 | E24: 25354.2 | F24: 23407.4 | G24: 20779.7 | I24: =IFERROR((G24/C24)^(1/4)-1,"n/m") -> -0.0033973685
A25: YoY growth % | D25: =(D24-C24)/ABS(C24) -> 0.2775238 | E25: =(E24-D24)/ABS(D24) -> -0.057828943 | F25: =(F24-E24)/ABS(E24) -> -0.076784123 | G25: =(G24-F24)/ABS(F24) -> -0.11225937
A26: Segment Adjusted EBITDA | B26: Key Figures p.4-5/120-121 | C26: n.d. | D26: 57 | E26: 385 | F26: 385.1 | G26: 333.1
A27: Adj. EBITDA margin, % of segment GMV | C27: =IFERROR(C26/C24,"n/m") -> n/m | D27: =IFERROR(D26/D24,"n/m") -> 0.0021181402 | E27: =IFERROR(E26/E24,"n/m") -> 0.015184861 | F27: =IFERROR(F26/F24,"n/m") -> 0.016452062 | G27: =IFERROR(G26/G24,"n/m") -> 0.016030068
A29: Segment: MENA
A30: Segment Revenue | B30: Key Figures p.4-5/120-121 | C30: 1562.9 | D30: 2218.4 | E30: 2700.8 | F30: 3527.8 | G30: 4033.7 | I30: =IFERROR((G30/C30)^(1/4)-1,"n/m") -> 0.2674858
A31: YoY growth % | D31: =(D30-C30)/ABS(C30) -> 0.41941263 | E31: =(E30-D30)/ABS(D30) -> 0.21745402 | F31: =(F30-E30)/ABS(E30) -> 0.30620557 | G31: =(G30-F30)/ABS(F30) -> 0.14340382
A32: Revenue mix, % of Total Segment Revenue | C32: =C30/C10 -> 0.24459295 | D32: =D30/D10 -> 0.24063608 | E32: =E30/E10 -> 0.25812371 | F32: =F30/F10 -> 0.27568691 | G32: =G30/G10 -> 0.2724847
A33: Segment GMV | B33: Key Figures p.4-5/120-121 | C33: 6755.9 | D33: 8542.3 | E33: 9959.3 | F33: 12825.9 | G33: 14644.3 | I33: =IFERROR((G33/C33)^(1/4)-1,"n/m") -> 0.21337866
A34: YoY growth % | D34: =(D33-C33)/ABS(C33) -> 0.26442073 | E34: =(E33-D33)/ABS(D33) -> 0.16588038 | F34: =(F33-E33)/ABS(E33) -> 0.28783147 | G34: =(G33-F33)/ABS(F33) -> 0.14177563
A35: Segment Adjusted EBITDA | B35: Key Figures p.4-5/120-121 | C35: n.d. | D35: 130.8 | E35: 304.6 | F35: 472.9 | G35: 546
A36: Adj. EBITDA margin, % of segment GMV | C36: =IFERROR(C35/C33,"n/m") -> n/m | D36: =IFERROR(D35/D33,"n/m") -> 0.015312035 | E36: =IFERROR(E35/E33,"n/m") -> 0.030584479 | F36: =IFERROR(F35/F33,"n/m") -> 0.036870707 | G36: =IFERROR(G35/G33,"n/m") -> 0.037284131
A38: Segment: Europe
A39: Segment Revenue | B39: Key Figures p.4-5/120-121 | C39: 571.4 | D39: 980.5 | E39: 1522.4 | F39: 1891.9 | G39: 2486.3 | I39: =IFERROR((G39/C39)^(1/4)-1,"n/m") -> 0.44428641
A40: YoY growth % | D40: =(D39-C39)/ABS(C39) -> 0.7159608 | E40: =(E39-D39)/ABS(D39) -> 0.55267721 | F40: =(F39-E39)/ABS(E39) -> 0.24270888 | G40: =(G39-F39)/ABS(F39) -> 0.31418151
A41: Revenue mix, % of Total Segment Revenue | C41: =C39/C10 -> 0.089423769 | D41: =D39/D10 -> 0.10635759 | E41: =E39/E10 -> 0.14550042 | F41: =F39/F10 -> 0.14784627 | G41: =G39/G10 -> 0.16795466
A42: Segment GMV | B42: Key Figures p.4-5/120-121 | C42: 2740.7 | D42: 4782.7 | E42: 7510 | F42: 8878.7 | G42: 9693.2 | I42: =IFERROR((G42/C42)^(1/4)-1,"n/m") -> 0.37135981
A43: YoY growth % | D43: =(D42-C42)/ABS(C42) -> 0.74506513 | E43: =(E42-D42)/ABS(D42) -> 0.57024275 | F43: =(F42-E42)/ABS(E42) -> 0.18225033 | G43: =(G42-F42)/ABS(F42) -> 0.091736403
A44: Segment Adjusted EBITDA | B44: Key Figures p.4-5/120-121 | C44: n.d. | D44: -158.5 | E44: -168.2 | F44: -77 | G44: -79.2
A45: Adj. EBITDA margin, % of segment GMV | C45: =IFERROR(C44/C42,"n/m") -> n/m | D45: =IFERROR(D44/D42,"n/m") -> -0.033140276 | E45: =IFERROR(E44/E42,"n/m") -> -0.022396804 | F45: =IFERROR(F44/F42,"n/m") -> -0.0086724408 | G45: =IFERROR(G44/G42,"n/m") -> -0.0081706764
A47: Segment: Americas
A48: Segment Revenue | B48: Key Figures p.4-5/120-121 | C48: 509.6 | D48: 681.6 | E48: 651 | F48: 939.6 | G48: 1057.6 | I48: =IFERROR((G48/C48)^(1/4)-1,"n/m") -> 0.20025357
A49: YoY growth % | D49: =(D48-C48)/ABS(C48) -> 0.33751962 | E49: =(E48-D48)/ABS(D48) -> -0.044894366 | F49: =(F48-E48)/ABS(E48) -> 0.44331797 | G49: =(G48-F48)/ABS(F48) -> 0.12558536
A50: Revenue mix, % of Total Segment Revenue | C50: =C48/C10 -> 0.079752105 | D50: =D48/D10 -> 0.073935068 | E50: =E48/E10 -> 0.062218059 | F50: =F48/F10 -> 0.073426901 | G50: =G48/G10 -> 0.071443047
...

Sheet Sources & Notes
A1: Sources & Notes
A3: Primary sources (all figures on Income Statement & Growth & Segments tabs)
A4: FY2021 actuals | B4: Delivery Hero SE, Annual Report 2021 (audited): Consolidated Statement of Profit or Loss (p.108–109), segment KPI table (p.76), Adjusted EBITDA reconciliation (p.131).
A5: FY2022 actuals | B5: Delivery Hero SE, Annual Report 2023 (audited): FY2022 restated comparative column, Consolidated Statement of Profit or Loss (p.90–91), Key Figures / segment table (p.4).
A6: FY2023 actuals | B6: Delivery Hero SE, Annual Report 2023 (audited): Consolidated Statement of Profit or Loss and Key Figures / segment table (p.4).
A7: FY2024 actuals | B7: Delivery Hero SE, Annual Report 2024 (audited): Consolidated Statement of Profit or Loss (p.145), Key Figures / segment table (p.4–5).
A8: FY2025 actuals | B8: Delivery Hero SE, Annual Report 2025 (audited): Consolidated Statement of Profit or Loss and Other Comprehensive Income (p.166), Key Figures / segment table (p.120–121).
A9: FY2025 like-for-like growth memo | B9: Delivery Hero, "Delivery Hero reports strong Q4, while business transforms into Everyday App" (FY2025 results release, Feb/Mar 2026).
A10: FY2026E guidance | B10: Delivery Hero FY2025 results release (Feb 27 / Mar 26, 2026) and Q1 2026 trading update (~May 2026): Total Segment Revenue +14–16%, GMV +8–10%, Adjusted EBITDA €910–960m (confidence raised to upper half at Q1 2026 update), Free Cash Flow >€200m.
A12: Modeling methodology
A13: Historical actuals (FY2021A–FY2025A) | B13: Line items reported by the company (Revenue, Cost of sales, Marketing, IT, G&A, Other operating income/expense, Impairment losses, Net interest, Other financial result, Share of JV result, Income taxes, NCI, EPS) are hardcoded inputs (blue). All subtotals (Gross profit, EBIT, EBT, Net result, Attributable to shareholders, margins, growth rates, CAGR) are LIVE FORMULAS that sum/derive from those inputs — they are not separately hardcoded, so they will recompute if any input is edited.
A14: FY2026E plan | B14: Built bottom-up from the Assumptions tab: Revenue and GMV grow off FY2025A at the guidance midpoint; cost lines are modeled as a constant % of Revenue (defaulted to the FY2025A actual ratio, editable); financing/tax/NCI lines are held flat at FY2025A EUR levels (editable). Adjusted EBITDA for FY2026E is shown at the company's own guidance midpoint (€935m) rather than derived bottom-up, because the IFRS-to-Adjusted-EBITDA bridge (D&A, share-based compensation, legal/restructuring add-backs) is not modeled at this line-item level — see Assumptions tab note.
A15: Growth formulas | B15: Standard YoY growth = (Current − Prior) / ABS(Prior); this avoids sign-inversion artifacts when the prior-year base is negative (e.g. EBIT, Net result during loss-making years). CAGR = (FY2025A / FY2021A)^(1/4) − 1, shown as "n/m" where the metric changes sign across the period.
A16: Rounding | B16: All reported figures are as published (EUR million, 1 decimal). Minor rounding differences of ±0.1–0.3 vs. a manual re-sum of components are inherent in the company's own disclosures.
A18: Comparability & portfolio notes
A19: Woowa Brothers / Baemin (South Korea) | B19: 88.5% stake closed March 4, 2021; consolidated into Asia segment from that date. As a Korean antitrust remedy, the pre-existing Delivery Hero Korea / Yogiyo business was classified held-for-sale from Jan 1, 2021 (excluded from Asia segment KPIs even before legal completion) and sold Oct 29, 2021 for €536.0m cash.
A20: Glovo (Spain, ~20 countries incl. Africa/Central Asia) | B20: Held as an equity-method associate (≤44.3% non-diluted) through H1 2022. Delivery Hero obtained control on July 4, 2022 (50.2% additionally acquired, 94.5% total) and has fully consolidated Glovo since — Europe segment (platform) and Integrated Verticals (quick commerce). FY2022 therefore includes only 6 months of Glovo vs. 12 months from FY2023 onward, inflating FY2023 Europe segment growth (+55.3%) mechanically. Delivery Hero's stake reached 99.4% by end-FY2024 via incremental minority buy-ins.
A21: Talabat (MENA) | B21: ~20% free float IPO'd on the Dubai Financial Market Dec 10, 2024 (~$2.0bn gross proceeds, upsized from an originally planned 15%). Delivery Hero retained ~80% and, per its own disclosure, this ownership change "did not alter DH's control over talabat; therefore, talabat continues to be fully consolidated." The public float is recognized as a non-controlling interest (see NCI turning positive in FY2025, reflecting Talabat's profitability).
A22: Foodpanda Asia portfolio optimization | B22: Denmark, Ghana, Slovakia and Slovenia exited prior to FY2024; Vietnam (Baemin brand) wound down Dec 8, 2023; Thailand exited May 23, 2025; Taiwan sale to Grab announced March 23, 2026 (pending, not yet closed). The company explicitly excludes these from its own "like-for-like" growth figures — including them would have reduced FY2025 GMV growth guidance by ~2 percentage points.
A23: Hyperinflation accounting (IAS 29) | B23: MENA, Americas and Integrated Verticals figures and growth rates are impacted by hyperinflation adjustments for Argentina and Türkiye (and, in earlier years, Lebanon and Ghana) throughout FY2022–FY2025.
A24: Total Segment Revenue vs. IFRS Revenue | B24: "Total Segment Revenue" is the company's own non-IFRS KPI (revenue before the reduction of vouchers, adjusted for reconciliation effects e.g. Glovo logistics/buy-sell netting); it is larger than IFRS "Revenue" on the face of the P&L. The two are not directly comparable line-by-line — see the reconciliation footnote in each Annual Report.
A25: PENDING — not reflected in these historicals | B25: Uber Technologies agreed (announced ~July 2026) to acquire Delivery Hero SE at an enterprise value of ~$14.8bn / €12.9bn; certain overlap markets (incl. foodora Scandinavia/Austria, Glovo Spain/Poland/Portugal, efood Greece, Yemeksepeti Turkey) are to be carved out to SSW Partners. Transaction is unclosed and subject to regulatory approval as of this model's preparation date (2026-08-17); secondary press reports on the expected closing date are inconsistent and are therefore not cited as fact in this model.
A27: Known limitations
A28: FY2021 NCI / attributable split | B28: Not separately itemized in the source extract used; the model treats FY2021 non-controlling interests as immaterial (Net result ≈ Attributable to shareholders), consistent with the reported EPS tying out to the full Net result.
A29: FY2021 segment Adjusted EBITDA | B29: Not available at the individual segment level in the sources reviewed; only the Group figure (−€795.6m) is populated for FY2021. Segment-level Adjusted EBITDA starts in FY2022.
A30: FY2026E Adjusted EBITDA | B30: Shown as the company's guidance midpoint, not derived bottom-up from the modeled IFRS EBIT — see "Modeling methodology" above.
